Workbook
Name enum_aa_booleanstatus: [1]importDropDownContent!$C$2:$C$3
Name enum_bd_assetmanage: [1]importDropDownContent!$A$2:$A$6
Name enum_taxDeductible: [1]importDropDownContent!$B$2:$B$3
Name refer_ucf_org_center.org_pure_tree_ref0: [1]参照!$C$3:$C$3

Sheet 资金报表科目
A1: 一级 | B1: 二级 | C1: 名词解释
A2: 业务收入 | B2: 平台硬件销售收入 | C2: 各个平台货款收入-退款部分。
B3: 服务收款 | C3: 目前业务暂不涉及，主要是后续用户达到一定量级后，会给用户提供其他AI服务
B4: 平台补贴收入
A5: 售后收入 | B5: 客户赔偿款 | C5: 用户因为机器以及零配件损坏，支付的赔偿款
B6: 供应商赔偿款 | C6: 供应商（合作商、物流、仓储供应商、员工等）因为机器以及零配件损坏，支付的赔偿款
A7: 营业外收入 | B7: 政府补贴收入 | C7: 从政府部门获取的各类补贴收益，包含注册资本金返还、房租补贴、研发补贴、高新技术补助等
B8: 利息收入 | C8: 理财收入、利息收入
B9: 其他收入 | C9: 验证款项等
B10: 收入合计
A11: 往来款项收入 | B11: 内部往来收入 | C11: 合并内关联方的往来款项
B12: 外部往来收入 | C12: 合并报表外的往来款项
A13: 投资款收入 | B13: 内部投资款收入 | C13: 合并内关联方的投资款，包含香港公司的对内投资
B14: 外部投资款收入
B15: 收款合计
A16: 往来款项支出 | B16: 内部往来支出 | C16: 合并内关联方的往来款项
B17: 外部往来支出 | C17: 合并报表外的往来款项
A18: 投资款支出 | B18: 内部投资款支出 | C18: 合并内关联方的投资款，包含香港公司的对内投资
A19: 人工成本 | B19: 实发工资 | C19: 销售、客服提成包含其中
B20: 奖金 | C20: 特殊项目奖金或者年终奖
B21: 社保（单位+个人）
B22: 公积金（单位+个人）
B23: 个税
B24: 福利费
B25: 补偿金
B26: 派遣费用 | C26: 支付给外包劳务公司的
B27: 顾问费 | C27: 支付给提供个人劳务的服务费
B28: 其他人工成本
A29: BONG MAX | B29: TCL平板电脑款项 | C29: TCL提货的款项支出，不包含前期的研发支出
B30: 保护套 | C30: 提货的款项支出，不包含模具等前期开发费用
B31: 包装盒 | C31: 提货的款项支出，不包含前期开发费用
B32: 充电器费用 | C32: 提货的款项支出，不包含前期开发费用
B33: 指学镜 | C33: 提货的款项支出，不包含前期开发费用
B34: 学习机系统授权费 | C34: 九学王等系统授权，该授权费用是根据学习机的装机数量确定
A35: BONG PRO | B35: BOE平板电脑款项 | C35: 提货的款项支出，不包含前期开发费用
B36: 保护套 | C36: 提货的款项支出，不包含前期开发费用
B37: 包装盒 | C37: 提货的款项支出，不包含前期开发费用
B38: 充电器费用 | C38: 提货的款项支出，不包含前期开发费用
B39: 指学镜 | C39: 提货的款项支出，不包含前期开发费用
B40: 学习机系统授权费 | C40: 九学王等系统授权，该授权费用是根据学习机的装机数量确定
...

Sheet 科目编码
A1: 手工码 | B1: *业务单元 | C1: 编码 | D1: *名称 | E1: 费用项目类型编码 | F1: 费用项目类型 | G1: 上级费用项目编码 | H1: 上级费用项目 | I1: 备注 | J1: 状态 | K1: 资产业务 | L1: 供应链业务 | M1: 费控业务 | N1: 营销业务 | O1: 财资业务 | P1: 资产业务分类 | Q1: 资产对应物料编码 | R1: 资产对应物料 | S1: 是否开票 | T1: 更新成本 | U1: 供应链对应物料编码 | V1: 供应链对应物料 | W1: 是否分摊 | X1: 排序
A2: 2236674769572331525 | B2: 企业账号级 | C2: Else01 | D2: 中转 | G2: Else | H2: 其他 | J2: 启用 | K2: 否 | L2: 否 | M2: 否 | N2: 否 | O2: 否 | S2: 否 | T2: 否 | V2: 0 | W2: 否 | X2: 999
A3: 2236674142531747845 | B3: 企业账号级 | C3: Else | D3: 其他 | J3: 启用 | K3: 否 | L3: 否 | M3: 否 | N3: 否 | O3: 否 | S3: 否 | T3: 否 | V3: 0 | W3: 否 | X3: 999
A4: 2225580121718259712 | B4: 企业账号级 | C4: Q3301 | D4: 理财收支 | G4: Q33 | H4: 理财 | J4: 启用 | K4: 否 | L4: 否 | M4: 否 | N4: 否 | O4: 否 | S4: 否 | T4: 否 | V4: 0 | W4: 否 | X4: 999
A5: 2225579984277733378 | B5: 企业账号级 | C5: Q33 | D5: 理财 | J5: 启用 | K5: 否 | L5: 否 | M5: 否 | N5: 否 | O5: 否 | S5: 否 | T5: 否 | V5: 0 | W5: 否 | X5: 999
A6: 2225576187526643714 | B6: 企业账号级 | C6: Q3209 | D6: 笔尖 | G6: Q32 | H6: 生产成本 | J6: 启用 | K6: 否 | L6: 否 | M6: 否 | N6: 否 | O6: 否 | S6: 否 | T6: 否 | V6: 0 | W6: 否 | X6: 999
A7: 2225576084447428617 | B7: 企业账号级 | C7: Q3208 | D7: 贴纸/说明书 | G7: Q32 | H7: 生产成本 | J7: 启用 | K7: 否 | L7: 否 | M7: 否 | N7: 否 | O7: 否 | S7: 否 | T7: 否 | V7: 0 | W7: 否 | X7: 999
A8: 2225575921240244228 | B8: 企业账号级 | C8: Q3207 | D8: 包机膜 | G8: Q32 | H8: 生产成本 | J8: 启用 | K8: 否 | L8: 否 | M8: 否 | N8: 否 | O8: 否 | S8: 否 | T8: 否 | V8: 0 | W8: 否 | X8: 999
A9: 2225575792421109769 | B9: 企业账号级 | C9: Q3206 | D9: 生产成本-员工报销 | G9: Q32 | H9: 生产成本 | J9: 启用 | K9: 否 | L9: 否 | M9: 否 | N9: 否 | O9: 否 | S9: 否 | T9: 否 | V9: 0 | W9: 否 | X9: 999
A10: 2225575637772402693 | B10: 企业账号级 | C10: Q3205 | D10: 低值易耗品采购 | G10: Q32 | H10: 生产成本 | J10: 启用 | K10: 否 | L10: 否 | M10: 否 | N10: 否 | O10: 否 | S10: 否 | T10: 否 | V10: 0 | W10: 否 | X10: 999
A11: 2225575508923383812 | B11: 企业账号级 | C11: Q3204 | D11: 运输费 | G11: Q32 | H11: 生产成本 | J11: 启用 | K11: 否 | L11: 否 | M11: 否 | N11: 否 | O11: 否 | S11: 否 | T11: 否 | V11: 0 | W11: 否 | X11: 999
A12: 2225575362894495751 | B12: 企业账号级 | C12: Q3203 | D12: 西溪首座仓库装修费 | G12: Q32 | H12: 生产成本 | J12: 启用 | K12: 否 | L12: 否 | M12: 否 | N12: 否 | O12: 否 | S12: 否 | T12: 否 | V12: 0 | W12: 否 | X12: 999
A13: 2225575199685738502 | B13: 企业账号级 | C13: Q3202 | D13: 西溪首座仓库物业水电费 | G13: Q32 | H13: 生产成本 | J13: 启用 | K13: 否 | L13: 否 | M13: 否 | N13: 否 | O13: 否 | S13: 否 | T13: 否 | V13: 0 | W13: 否 | X13: 999
A14: 2225574692909481986 | B14: 企业账号级 | C14: Q3201 | D14: 西溪首座仓库租金 | G14: Q32 | H14: 生产成本 | J14: 启用 | K14: 否 | L14: 否 | M14: 否 | N14: 否 | O14: 否 | S14: 否 | T14: 否 | V14: 0 | W14: 否 | X14: 999
A15: 2225574443801378816 | B15: 企业账号级 | C15: Q32 | D15: 生产成本 | J15: 启用 | K15: 否 | L15: 否 | M15: 否 | N15: 否 | O15: 否 | S15: 否 | T15: 否 | V15: 0 | W15: 否 | X15: 999
A16: 2225570054313345030 | B16: 企业账号级 | C16: Q3104 | D16: 违约金支出 | G16: Q31 | H16: 营业外支出 | J16: 启用 | K16: 否 | L16: 否 | M16: 否 | N16: 否 | O16: 否 | S16: 否 | T16: 否 | V16: 0 | W16: 否 | X16: 999
A17: 2225569444459446277 | B17: 企业账号级 | C17: Q2807 | D17: 软件服务费 | G17: Q28 | H17: 服务费 | J17: 启用 | K17: 否 | L17: 否 | M17: 否 | N17: 否 | O17: 否 | S17: 否 | T17: 否 | V17: 0 | W17: 否 | X17: 999
A18: 2225547351117791241 | B18: 企业账号级 | C18: Q2209 | D18: 其他平台扣款 | G18: Q22 | H18: 平台运营 | J18: 启用 | K18: 否 | L18: 否 | M18: 否 | N18: 否 | O18: 否 | S18: 否 | T18: 否 | V18: 0 | W18: 否 | X18: 999
A19: 2225547144959361032 | B19: 企业账号级 | C19: Q2208 | D19: 平台推荐佣金 | G19: Q22 | H19: 平台运营 | J19: 启用 | K19: 否 | L19: 否 | M19: 否 | N19: 否 | O19: 否 | S19: 否 | T19: 否 | V19: 0 | W19: 否 | X19: 999
A20: 2225546973190553601 | B20: 企业账号级 | C20: Q2207 | D20: 平台积分扣款 | G20: Q22 | H20: 平台运营 | J20: 启用 | K20: 否 | L20: 否 | M20: 否 | N20: 否 | O20: 否 | S20: 否 | T20: 否 | V20: 0 | W20: 否 | X20: 999
A21: 2225546715461058564 | B21: 企业账号级 | C21: Q2206 | D21: 消费者赔付 | G21: Q22 | H21: 平台运营 | J21: 启用 | K21: 否 | L21: 否 | M21: 否 | N21: 否 | O21: 否 | S21: 否 | T21: 否 | V21: 0 | W21: 否 | X21: 999
A22: 2225546612413300736 | B22: 企业账号级 | C22: Q2205 | D22: 权益保险 | G22: Q22 | H22: 平台运营 | J22: 启用 | K22: 否 | L22: 否 | M22: 否 | N22: 否 | O22: 否 | S22: 否 | T22: 否 | V22: 0 | W22: 否 | X22: 999
A23: 2225546423434739718 | B23: 企业账号级 | C23: Q2204 | D23: 分期服务费 | G23: Q22 | H23: 平台运营 | J23: 启用 | K23: 否 | L23: 否 | M23: 否 | N23: 否 | O23: 否 | S23: 否 | T23: 否 | V23: 0 | W23: 否 | X23: 999
A24: 2225498637598720000 | B24: 企业账号级 | C24: Q1507 | D24: 无问芯穹充值费用 | G24: Q15 | H24: 服务器算法充值 | J24: 启用 | K24: 否 | L24: 否 | M24: 否 | N24: 否 | O24: 否 | S24: 否 | T24: 否 | V24: 0 | W24: 否 | X24: 999
A25: 2225498491599716358 | B25: 企业账号级 | C25: Q1506 | D25: 硅基流动充值费用 | G25: Q15 | H25: 服务器算法充值 | J25: 启用 | K25: 否 | L25: 否 | M25: 否 | N25: 否 | O25: 否 | S25: 否 | T25: 否 | V25: 0 | W25: 否 | X25: 999
A26: 2225497855944556547 | B26: 企业账号级 | C26: Q1402 | D26: 产品开发-员工报销 | G26: Q14 | H26: 其他产品开发 | J26: 启用 | K26: 否 | L26: 否 | M26: 否 | N26: 否 | O26: 否 | S26: 否 | T26: 否 | V26: 0 | W26: 否 | X26: 999
A27: 2225337902772518913 | B27: 企业账号级 | C27: Q0103 | D27: 平台补贴收入 | G27: Q01 | H27: 业务收入 | J27: 启用 | K27: 否 | L27: 否 | M27: 否 | N27: 否 | O27: 否 | S27: 否 | T27: 否 | W27: 否 | X27: 999
A28: 2200402851648241672 | B28: 企业账号级 | C28: Q2302 | D28: 转介绍佣金 | G28: Q23 | H28: 私域运营 | J28: 启用 | K28: 否 | L28: 否 | M28: 否 | N28: 否 | O28: 否 | S28: 否 | T28: 否 | W28: 否 | X28: 999
A29: 2184633380988518407 | B29: 企业账号级 | C29: Q3103 | D29: 滞纳金支出 | G29: Q31 | H29: 营业外支出 | J29: 启用 | K29: 是 | L29: 是 | M29: 是 | N29: 是 | O29: 是 | S29: 否 | T29: 否 | W29: 否 | X29: 999
A30: 2184633380988518406 | B30: 企业账号级 | C30: Q3102 | D30: 罚款支出 | G30: Q31 | H30: 营业外支出 | J30: 启用 | K30: 是 | L30: 是 | M30: 是 | N30: 是 | O30: 是 | S30: 否 | T30: 否 | W30: 否 | X30: 999
A31: 2184633380988518405 | B31: 企业账号级 | C31: Q3101 | D31: 手续费 | G31: Q31 | H31: 营业外支出 | J31: 启用 | K31: 是 | L31: 是 | M31: 是 | N31: 是 | O31: 是 | S31: 否 | T31: 否 | W31: 否 | X31: 999
A32: 2184633380988518404 | B32: 企业账号级 | C32: Q3004 | D32: 企业所得税 | G32: Q30 | H32: 税费成本 | J32: 启用 | K32: 是 | L32: 是 | M32: 是 | N32: 是 | O32: 是 | S32: 否 | T32: 否 | W32: 否 | X32: 999
A33: 2184633380988518403 | B33: 企业账号级 | C33: Q3003 | D33: 印花税 | G33: Q30 | H33: 税费成本 | J33: 启用 | K33: 是 | L33: 是 | M33: 是 | N33: 是 | O33: 是 | S33: 否 | T33: 否 | W33: 否 | X33: 999
A34: 2184633372398583822 | B34: 企业账号级 | C34: Q3002 | D34: 附加税 | G34: Q30 | H34: 税费成本 | J34: 启用 | K34: 是 | L34: 是 | M34: 是 | N34: 是 | O34: 是 | S34: 否 | T34: 否 | W34: 否 | X34: 999
A35: 2184633372398583821 | B35: 企业账号级 | C35: Q3001 | D35: 增值税 | G35: Q30 | H35: 税费成本 | J35: 启用 | K35: 是 | L35: 是 | M35: 是 | N35: 是 | O35: 是 | S35: 否 | T35: 否 | W35: 否 | X35: 999
A36: 2184633372398583820 | B36: 企业账号级 | C36: Q29010 | D36: 其他办公费用 | G36: Q29 | H36: 办公费用 | J36: 启用 | K36: 是 | L36: 是 | M36: 是 | N36: 是 | O36: 是 | S36: 否 | T36: 否 | W36: 否 | X36: 999
A37: 2184633372398583819 | B37: 企业账号级 | C37: Q2909 | D37: 总经办报销费用 | G37: Q29 | H37: 办公费用 | J37: 启用 | K37: 是 | L37: 是 | M37: 是 | N37: 是 | O37: 是 | S37: 否 | T37: 否 | W37: 否 | X37: 999
A38: 2184633372398583818 | B38: 企业账号级 | C38: Q2908 | D38: 办公设备租赁费 | G38: Q29 | H38: 办公费用 | J38: 启用 | K38: 是 | L38: 是 | M38: 是 | N38: 是 | O38: 是 | S38: 否 | T38: 否 | W38: 否 | X38: 999
... A152: 2184633192009957380 | B152: 企业账号级 | C152: Q0101 | D152: 平台硬件销售收入 | G152: Q01 | H152: 业务收入 | J152: 启用 | K152: 是 | L152: 是 | M152: 是 | N152: 是 | O152: 是 | S152: 否 | T152: 否 | W152: 否 | X152: 999
A153: 2184632444685647874 | B153: 企业账号级 | C153: Q31 | D153: 营业外支出 | J153: 启用 | K153: 是 | L153: 是 | M153: 是 | N153: 是 | O153: 是 | S153: 否 | T153: 否 | W153: 否 | X153: 999
...

Sheet 问题
A1: 1、 | B1: 理财的利息收入，目前费用项目放在利息收入里，王妍的表里是单独在最后加了一行理财收支，这个费用项目只包括本金部分
A2: 2、 | B2: 汇兑损益的费用项目修改为手续费
P4: 统一修改为汇兑损益
P8: 统一修改为汇兑损益
A11: 3、 | B11: 这两个应该是外部往来支出？
A17: 4、 | B17: 理财收支是否要分开
A23: 5、 | B23: 这样会导致该项目支出金额为负数，是否要紧
A32: 6、 | B32: 合并抵消的要单独标注
A34: 7、 | B34: 这个业务是啥
A40: 8、 | B40: 其他还有一些费用项目会存在退款导致资金流出为负数的情况，比方物业费退款、抖音投放退款
A42: 9、 | B42: 费用项目应该是社保（单位+个人）
R45: 已修改
A49: 10、 | B49: 2楼的费用项目应该是生产成本下面的Q3201，现在Q2702是归在管理费用里了
A56: 11、 | B56: 2楼应该是制造费用
A73: 12、 | B73: 公司内部不同账户之间划款费用名称应改为内部往来收入

Sheet 合并抵消
A1: 月份 | B1: 科目编码 | C1: 科目名称 | D1: 日期 | E1: 费用项目编码 | F1: 费用项目名称 | G1: 核算账簿 | H1: 凭证号 | I1: 摘要 | J1: 借方本币 | K1: 贷方本币
A2: 1月 | B2: 100201 | D2: 2025-01-21 | E2: Q0401 | H2: 记-1
A3: 1月 | B3: 100201 | D3: 2025-01-23 | E3: Q0401 | H3: 记-33
A4: 1月 | B4: 100201 | D4: 2025-01-21 | E4: Q0601 | H4: 记-81
A5: 1月 | B5: 100201 | D5: 2025-01-23 | E5: Q0601 | H5: 记-117
A6: 2月 | B6: 100201 | D6: 2025-02-28 | E6: Q0401 | H6: 记-98
A7: 2月 | B7: 100201 | D7: 2025-02-27 | E7: Q0401 | H7: 记-84
A8: 2月 | B8: 100201 | D8: 2025-02-26 | E8: Q0401 | H8: 记-77
A9: 2月 | B9: 100201 | D9: 2025-02-14 | E9: Q0401 | H9: 记-41
A10: 2月 | B10: 100201 | D10: 2025-02-28 | E10: Q0601 | H10: 记-35
A11: 2月 | B11: 100201 | D11: 2025-02-26 | E11: Q0601 | H11: 记-25
A12: 2月 | B12: 100201 | D12: 2025-02-28 | E12: Q0601 | H12: 记-99
A13: 2月 | B13: 100201 | D13: 2025-02-14 | E13: Q0601 | H13: 记-10
... A97: 7月 | B97: 100202 | D97: 2025-07-09 | E97: Q0501 | H97: 记-82
A98: 9月 | B98: 100201 | C98: 银行存款_人民币户 | D98: 2025-09-24 | E98: Q0401 | F98: 内部往来收入 | G98: 浙江精准学科技有限公司 | H98: 记-2 | I98: 关联交易-123456 | J98: 19999 | K98: 0

Sheet 分月实际收支-集团合并
A1: 公司：集团合并
A2: 一级 | B2: 辅助列 | C2: 二级 | D2: 三级 | E2: 三级科目对应编码 | F2: 1月 | G2: 2月 | H2: 3月 | I2: 4月 | J2: 5月 | K2: 6月 | L2: 7月 | M2: 8月 | N2: 9月 | O2: 10月 | P2: 11月 | Q2: 12月 | R2: 本年合计
A3: 收入 | B3: 学习机销售收入 | C3: 业务收入 | D3: 平台硬件销售收入 | E3: Q0101 | F3: =浙江精准学!F3+知识跳跳!F3+海南精准学!F3+实时查!F3+目标准!F3+'SMART LEARNING HOLDING'!F3+'SMART AI LIMITED'!F3+'HK01'!F3-(SUMIFS(合并抵消!$J:$J,合并抵消!$E:$E,$E3,合并抵消!$A:$A,F$2)-SUMIFS(合并抵消!$K:$K,合并抵消!$E:$E,$E3,合并抵消!$A:$A,F$2)) | G3: =浙江精准学!G3+知识跳跳!G3+海南精准学!G3+实时查!G3+目标准!G3+'SMART LEARNING HOLDING'!G3+'SMART AI LIMITED'!G3+'HK01'!G3-(SUMIFS(合并抵消!$J:$J,合并抵消!$E:$E,$E3,合并抵消!$A:$A,G$2)-SUMIFS(合并抵消!$K:$K,合并抵消!$E:$E,$E3,合并抵消!$A:$A,G$2)) | H3: =浙江精准学!H3+知识跳跳!H3+海南精准学!H3+实时查!H3+目标准!H3+'SMART LEARNING HOLDING'!H3+'SMART AI LIMITED'!H3+'HK01'!H3-(SUMIFS(合并抵消!$J:$J,合并抵消!$E:$E,$E3,合并抵消!$A:$A,H$2)-SUMIFS(合并抵消!$K:$K,合并抵消!$E:$E,$E3,合并抵消!$A:$A,H$2)) | I3: =浙江精准学!I3+知识跳跳!I3+海南精准学!I3+实时查!I3+目标准!I3+'SMART LEARNING HOLDING'!I3+'SMART AI LIMITED'!I3+'HK01'!I3-(SUMIFS(合并抵消!$J:$J,合并抵消!$E:$E,$E3,合并抵消!$A:$A,I$2)-SUMIFS(合并抵消!$K:$K,合并抵消!$E:$E,$E3,合并抵消!$A:$A,I$2)) | J3: =浙江精准学!J3+知识跳跳!J3+海南精准学!J3+实时查!J3+目标准!J3+'SMART LEARNING HOLDING'!J3+'SMART AI LIMITED'!J3+'HK01'!J3-(SUMIFS(合并抵消!$J:$J,合并抵消!$E:$E,$E3,合并抵消!$A:$A,J$2)-SUMIFS(合并抵消!$K:$K,合并抵消!$E:$E,$E3,合并抵消!$A:$A,J$2)) | K3: =浙江精准学!K3+知识跳跳!K3+海南精准学!K3+实时查!K3+目标准!K3+'SMART LEARNING HOLDING'!K3+'SMART AI LIMITED'!K3+'HK01'!K3-(SUMIFS(合并抵消!$J:$J,合并抵消!$E:$E,$E3,合并抵消!$A:$A,K$2)-SUMIFS(合并抵消!$K:$K,合并抵消!$E:$E,$E3,合并抵消!$A:$A,K$2)) | L3: =浙江精准学!L3+知识跳跳!L3+海南精准学!L3+实时查!L3+目标准!L3+'SMART LEARNING HOLDING'!L3+'SMART AI LIMITED'!L3+'HK01'!L3-(SUMIFS(合并抵消!$J:$J,合并抵消!$E:$E,$E3,合并抵消!$A:$A,L$2)-SUMIFS(合并抵消!$K:$K,合并抵消!$E:$E,$E3,合并抵消!$A:$A,L$2)) | M3: =浙江精准学!M3+知识跳跳!M3+海南精准学!M3+实时查!M3+目标准!M3+'SMART LEARNING HOLDING'!M3+'SMART AI LIMITED'!M3+'HK01'!M3-(SUMIFS(合并抵消!$J:$J,合并抵消!$E:$E,$E3,合并抵消!$A:$A,M$2)-SUMIFS(合并抵消!$K:$K,合并抵消!$E:$E,$E3,合并抵消!$A:$A,M$2)) | ... Q3: =浙江精准学!Q3+知识跳跳!Q3+海南精准学!Q3+实时查!Q3+目标准!Q3+'SMART LEARNING HOLDING'!Q3+'SMART AI LIMITED'!Q3+'HK01'!Q3-(SUMIFS(合并抵消!$J:$J,合并抵消!$E:$E,$E3,合并抵消!$A:$A,Q$2)-SUMIFS(合并抵消!$K:$K,合并抵消!$E:$E,$E3,合并抵消!$A:$A,Q$2)) | R3: =SUM(F3:Q3)
A4: 收入 | B4: 学习机销售收入 | D4: 服务收款 | E4: Q0102 | F4: =浙江精准学!F4+知识跳跳!F4+海南精准学!F4+实时查!F4+目标准!F4+'SMART LEARNING HOLDING'!F4+'SMART AI LIMITED'!F4+'HK01'!F4-(SUMIFS(合并抵消!$J:$J,合并抵消!$E:$E,$E4,合并抵消!$A:$A,F$2)-SUMIFS(合并抵消!$K:$K,合并抵消!$E:$E,$E4,合并抵消!$A:$A,F$2)) | G4: =浙江精准学!G4+知识跳跳!G4+海南精准学!G4+实时查!G4+目标准!G4+'SMART LEARNING HOLDING'!G4+'SMART AI LIMITED'!G4+'HK01'!G4-(SUMIFS(合并抵消!$J:$J,合并抵消!$E:$E,$E4,合并抵消!$A:$A,G$2)-SUMIFS(合并抵消!$K:$K,合并抵消!$E:$E,$E4,合并抵消!$A:$A,G$2)) | H4: =浙江精准学!H4+知识跳跳!H4+海南精准学!H4+实时查!H4+目标准!H4+'SMART LEARNING HOLDING'!H4+'SMART AI LIMITED'!H4+'HK01'!H4-(SUMIFS(合并抵消!$J:$J,合并抵消!$E:$E,$E4,合并抵消!$A:$A,H$2)-SUMIFS(合并抵消!$K:$K,合并抵消!$E:$E,$E4,合并抵消!$A:$A,H$2)) | I4: =浙江精准学!I4+知识跳跳!I4+海南精准学!I4+实时查!I4+目标准!I4+'SMART LEARNING HOLDING'!I4+'SMART AI LIMITED'!I4+'HK01'!I4-(SUMIFS(合并抵消!$J:$J,合并抵消!$E:$E,$E4,合并抵消!$A:$A,I$2)-SUMIFS(合并抵消!$K:$K,合并抵消!$E:$E,$E4,合并抵消!$A:$A,I$2)) | J4: =浙江精准学!J4+知识跳跳!J4+海南精准学!J4+实时查!J4+目标准!J4+'SMART LEARNING HOLDING'!J4+'SMART AI LIMITED'!J4+'HK01'!J4-(SUMIFS(合并抵消!$J:$J,合并抵消!$E:$E,$E4,合并抵消!$A:$A,J$2)-SUMIFS(合并抵消!$K:$K,合并抵消!$E:$E,$E4,合并抵消!$A:$A,J$2)) | K4: =浙江精准学!K4+知识跳跳!K4+海南精准学!K4+实时查!K4+目标准!K4+'SMART LEARNING HOLDING'!K4+'SMART AI LIMITED'!K4+'HK01'!K4-(SUMIFS(合并抵消!$J:$J,合并抵消!$E:$E,$E4,合并抵消!$A:$A,K$2)-SUMIFS(合并抵消!$K:$K,合并抵消!$E:$E,$E4,合并抵消!$A:$A,K$2)) | L4: =浙江精准学!L4+知识跳跳!L4+海南精准学!L4+实时查!L4+目标准!L4+'SMART LEARNING HOLDING'!L4+'SMART AI LIMITED'!L4+'HK01'!L4-(SUMIFS(合并抵消!$J:$J,合并抵消!$E:$E,$E4,合并抵消!$A:$A,L$2)-SUMIFS(合并抵消!$K:$K,合并抵消!$E:$E,$E4,合并抵消!$A:$A,L$2)) | M4: =浙江精准学!M4+知识跳跳!M4+海南精准学!M4+实时查!M4+目标准!M4+'SMART LEARNING HOLDING'!M4+'SMART AI LIMITED'!M4+'HK01'!M4-(SUMIFS(合并抵消!$J:$J,合并抵消!$E:$E,$E4,合并抵消!$A:$A,M$2)-SUMIFS(合并抵消!$K:$K,合并抵消!$E:$E,$E4,合并抵消!$A:$A,M$2)) | ... Q4: =浙江精准学!Q4+知识跳跳!Q4+海南精准学!Q4+实时查!Q4+目标准!Q4+'SMART LEARNING HOLDING'!Q4+'SMART AI LIMITED'!Q4+'HK01'!Q4-(SUMIFS(合并抵消!$J:$J,合并抵消!$E:$E,$E4,合并抵消!$A:$A,Q$2)-SUMIFS(合并抵消!$K:$K,合并抵消!$E:$E,$E4,合并抵消!$A:$A,Q$2)) | R4: =SUM(F4:Q4)
A5: 收入 | B5: 学习机销售收入 | D5: 平台补贴收入 | E5: Q0103 | F5: =浙江精准学!F5+知识跳跳!F5+海南精准学!F5+实时查!F5+目标准!F5+'SMART LEARNING HOLDING'!F5+'SMART AI LIMITED'!F5+'HK01'!F5-(SUMIFS(合并抵消!$J:$J,合并抵消!$E:$E,$E5,合并抵消!$A:$A,F$2)-SUMIFS(合并抵消!$K:$K,合并抵消!$E:$E,$E5,合并抵消!$A:$A,F$2)) | G5: =浙江精准学!G5+知识跳跳!G5+海南精准学!G5+实时查!G5+目标准!G5+'SMART LEARNING HOLDING'!G5+'SMART AI LIMITED'!G5+'HK01'!G5-(SUMIFS(合并抵消!$J:$J,合并抵消!$E:$E,$E5,合并抵消!$A:$A,G$2)-SUMIFS(合并抵消!$K:$K,合并抵消!$E:$E,$E5,合并抵消!$A:$A,G$2)) | H5: =浙江精准学!H5+知识跳跳!H5+海南精准学!H5+实时查!H5+目标准!H5+'SMART LEARNING HOLDING'!H5+'SMART AI LIMITED'!H5+'HK01'!H5-(SUMIFS(合并抵消!$J:$J,合并抵消!$E:$E,$E5,合并抵消!$A:$A,H$2)-SUMIFS(合并抵消!$K:$K,合并抵消!$E:$E,$E5,合并抵消!$A:$A,H$2)) | I5: =浙江精准学!I5+知识跳跳!I5+海南精准学!I5+实时查!I5+目标准!I5+'SMART LEARNING HOLDING'!I5+'SMART AI LIMITED'!I5+'HK01'!I5-(SUMIFS(合并抵消!$J:$J,合并抵消!$E:$E,$E5,合并抵消!$A:$A,I$2)-SUMIFS(合并抵消!$K:$K,合并抵消!$E:$E,$E5,合并抵消!$A:$A,I$2)) | J5: =浙江精准学!J5+知识跳跳!J5+海南精准学!J5+实时查!J5+目标准!J5+'SMART LEARNING HOLDING'!J5+'SMART AI LIMITED'!J5+'HK01'!J5-(SUMIFS(合并抵消!$J:$J,合并抵消!$E:$E,$E5,合并抵消!$A:$A,J$2)-SUMIFS(合并抵消!$K:$K,合并抵消!$E:$E,$E5,合并抵消!$A:$A,J$2)) | K5: =浙江精准学!K5+知识跳跳!K5+海南精准学!K5+实时查!K5+目标准!K5+'SMART LEARNING HOLDING'!K5+'SMART AI LIMITED'!K5+'HK01'!K5-(SUMIFS(合并抵消!$J:$J,合并抵消!$E:$E,$E5,合并抵消!$A:$A,K$2)-SUMIFS(合并抵消!$K:$K,合并抵消!$E:$E,$E5,合并抵消!$A:$A,K$2)) | L5: =浙江精准学!L5+知识跳跳!L5+海南精准学!L5+实时查!L5+目标准!L5+'SMART LEARNING HOLDING'!L5+'SMART AI LIMITED'!L5+'HK01'!L5-(SUMIFS(合并抵消!$J:$J,合并抵消!$E:$E,$E5,合并抵消!$A:$A,L$2)-SUMIFS(合并抵消!$K:$K,合并抵消!$E:$E,$E5,合并抵消!$A:$A,L$2)) | M5: =浙江精准学!M5+知识跳跳!M5+海南精准学!M5+实时查!M5+目标准!M5+'SMART LEARNING HOLDING'!M5+'SMART AI LIMITED'!M5+'HK01'!M5-(SUMIFS(合并抵消!$J:$J,合并抵消!$E:$E,$E5,合并抵消!$A:$A,M$2)-SUMIFS(合并抵消!$K:$K,合并抵消!$E:$E,$E5,合并抵消!$A:$A,M$2)) | ... Q5: =浙江精准学!Q5+知识跳跳!Q5+海南精准学!Q5+实时查!Q5+目标准!Q5+'SMART LEARNING HOLDING'!Q5+'SMART AI LIMITED'!Q5+'HK01'!Q5-(SUMIFS(合并抵消!$J:$J,合并抵消!$E:$E,$E5,合并抵消!$A:$A,Q$2)-SUMIFS(合并抵消!$K:$K,合并抵消!$E:$E,$E5,合并抵消!$A:$A,Q$2)) | R5: =SUM(F5:Q5)
A6: 收入 | B6: 自习室收入 | D6: 自习室收入 | E6: Q0104 | F6: =浙江精准学!F6+知识跳跳!F6+海南精准学!F6+实时查!F6+目标准!F6+'SMART LEARNING HOLDING'!F6+'SMART AI LIMITED'!F6+'HK01'!F6-(SUMIFS(合并抵消!$J:$J,合并抵消!$E:$E,$E6,合并抵消!$A:$A,F$2)-SUMIFS(合并抵消!$K:$K,合并抵消!$E:$E,$E6,合并抵消!$A:$A,F$2)) | G6: =浙江精准学!G6+知识跳跳!G6+海南精准学!G6+实时查!G6+目标准!G6+'SMART LEARNING HOLDING'!G6+'SMART AI LIMITED'!G6+'HK01'!G6-(SUMIFS(合并抵消!$J:$J,合并抵消!$E:$E,$E6,合并抵消!$A:$A,G$2)-SUMIFS(合并抵消!$K:$K,合并抵消!$E:$E,$E6,合并抵消!$A:$A,G$2)) | H6: =浙江精准学!H6+知识跳跳!H6+海南精准学!H6+实时查!H6+目标准!H6+'SMART LEARNING HOLDING'!H6+'SMART AI LIMITED'!H6+'HK01'!H6-(SUMIFS(合并抵消!$J:$J,合并抵消!$E:$E,$E6,合并抵消!$A:$A,H$2)-SUMIFS(合并抵消!$K:$K,合并抵消!$E:$E,$E6,合并抵消!$A:$A,H$2)) | I6: =浙江精准学!I6+知识跳跳!I6+海南精准学!I6+实时查!I6+目标准!I6+'SMART LEARNING HOLDING'!I6+'SMART AI LIMITED'!I6+'HK01'!I6-(SUMIFS(合并抵消!$J:$J,合并抵消!$E:$E,$E6,合并抵消!$A:$A,I$2)-SUMIFS(合并抵消!$K:$K,合并抵消!$E:$E,$E6,合并抵消!$A:$A,I$2)) | J6: =浙江精准学!J6+知识跳跳!J6+海南精准学!J6+实时查!J6+目标准!J6+'SMART LEARNING HOLDING'!J6+'SMART AI LIMITED'!J6+'HK01'!J6-(SUMIFS(合并抵消!$J:$J,合并抵消!$E:$E,$E6,合并抵消!$A:$A,J$2)-SUMIFS(合并抵消!$K:$K,合并抵消!$E:$E,$E6,合并抵消!$A:$A,J$2)) | K6: =浙江精准学!K6+知识跳跳!K6+海南精准学!K6+实时查!K6+目标准!K6+'SMART LEARNING HOLDING'!K6+'SMART AI LIMITED'!K6+'HK01'!K6-(SUMIFS(合并抵消!$J:$J,合并抵消!$E:$E,$E6,合并抵消!$A:$A,K$2)-SUMIFS(合并抵消!$K:$K,合并抵消!$E:$E,$E6,合并抵消!$A:$A,K$2)) | L6: =浙江精准学!L6+知识跳跳!L6+海南精准学!L6+实时查!L6+目标准!L6+'SMART LEARNING HOLDING'!L6+'SMART AI LIMITED'!L6+'HK01'!L6-(SUMIFS(合并抵消!$J:$J,合并抵消!$E:$E,$E6,合并抵消!$A:$A,L$2)-SUMIFS(合并抵消!$K:$K,合并抵消!$E:$E,$E6,合并抵消!$A:$A,L$2)) | M6: =浙江精准学!M6+知识跳跳!M6+海南精准学!M6+实时查!M6+目标准!M6+'SMART LEARNING HOLDING'!M6+'SMART AI LIMITED'!M6+'HK01'!M6-(SUMIFS(合并抵消!$J:$J,合并抵消!$E:$E,$E6,合并抵消!$A:$A,M$2)-SUMIFS(合并抵消!$K:$K,合并抵消!$E:$E,$E6,合并抵消!$A:$A,M$2)) | ... Q6: =浙江精准学!Q6+知识跳跳!Q6+海南精准学!Q6+实时查!Q6+目标准!Q6+'SMART LEARNING HOLDING'!Q6+'SMART AI LIMITED'!Q6+'HK01'!Q6-(SUMIFS(合并抵消!$J:$J,合并抵消!$E:$E,$E6,合并抵消!$A:$A,Q$2)-SUMIFS(合并抵消!$K:$K,合并抵消!$E:$E,$E6,合并抵消!$A:$A,Q$2))
A7: 收入 | B7: 售后收入 | C7: 售后收入 | D7: 客户赔偿款 | E7: Q0201 | F7: =浙江精准学!F7+知识跳跳!F7+海南精准学!F7+实时查!F7+目标准!F7+'SMART LEARNING HOLDING'!F7+'SMART AI LIMITED'!F7+'HK01'!F7-(SUMIFS(合并抵消!$J:$J,合并抵消!$E:$E,$E7,合并抵消!$A:$A,F$2)-SUMIFS(合并抵消!$K:$K,合并抵消!$E:$E,$E7,合并抵消!$A:$A,F$2)) | G7: =浙江精准学!G7+知识跳跳!G7+海南精准学!G7+实时查!G7+目标准!G7+'SMART LEARNING HOLDING'!G7+'SMART AI LIMITED'!G7+'HK01'!G7-(SUMIFS(合并抵消!$J:$J,合并抵消!$E:$E,$E7,合并抵消!$A:$A,G$2)-SUMIFS(合并抵消!$K:$K,合并抵消!$E:$E,$E7,合并抵消!$A:$A,G$2)) | H7: =浙江精准学!H7+知识跳跳!H7+海南精准学!H7+实时查!H7+目标准!H7+'SMART LEARNING HOLDING'!H7+'SMART AI LIMITED'!H7+'HK01'!H7-(SUMIFS(合并抵消!$J:$J,合并抵消!$E:$E,$E7,合并抵消!$A:$A,H$2)-SUMIFS(合并抵消!$K:$K,合并抵消!$E:$E,$E7,合并抵消!$A:$A,H$2)) | I7: =浙江精准学!I7+知识跳跳!I7+海南精准学!I7+实时查!I7+目标准!I7+'SMART LEARNING HOLDING'!I7+'SMART AI LIMITED'!I7+'HK01'!I7-(SUMIFS(合并抵消!$J:$J,合并抵消!$E:$E,$E7,合并抵消!$A:$A,I$2)-SUMIFS(合并抵消!$K:$K,合并抵消!$E:$E,$E7,合并抵消!$A:$A,I$2)) | J7: =浙江精准学!J7+知识跳跳!J7+海南精准学!J7+实时查!J7+目标准!J7+'SMART LEARNING HOLDING'!J7+'SMART AI LIMITED'!J7+'HK01'!J7-(SUMIFS(合并抵消!$J:$J,合并抵消!$E:$E,$E7,合并抵消!$A:$A,J$2)-SUMIFS(合并抵消!$K:$K,合并抵消!$E:$E,$E7,合并抵消!$A:$A,J$2)) | K7: =浙江精准学!K7+知识跳跳!K7+海南精准学!K7+实时查!K7+目标准!K7+'SMART LEARNING HOLDING'!K7+'SMART AI LIMITED'!K7+'HK01'!K7-(SUMIFS(合并抵消!$J:$J,合并抵消!$E:$E,$E7,合并抵消!$A:$A,K$2)-SUMIFS(合并抵消!$K:$K,合并抵消!$E:$E,$E7,合并抵消!$A:$A,K$2)) | L7: =浙江精准学!L7+知识跳跳!L7+海南精准学!L7+实时查!L7+目标准!L7+'SMART LEARNING HOLDING'!L7+'SMART AI LIMITED'!L7+'HK01'!L7-(SUMIFS(合并抵消!$J:$J,合并抵消!$E:$E,$E7,合并抵消!$A:$A,L$2)-SUMIFS(合并抵消!$K:$K,合并抵消!$E:$E,$E7,合并抵消!$A:$A,L$2)) | M7: =浙江精准学!M7+知识跳跳!M7+海南精准学!M7+实时查!M7+目标准!M7+'SMART LEARNING HOLDING'!M7+'SMART AI LIMITED'!M7+'HK01'!M7-(SUMIFS(合并抵消!$J:$J,合并抵消!$E:$E,$E7,合并抵消!$A:$A,M$2)-SUMIFS(合并抵消!$K:$K,合并抵消!$E:$E,$E7,合并抵消!$A:$A,M$2)) | ... Q7: =浙江精准学!Q7+知识跳跳!Q7+海南精准学!Q7+实时查!Q7+目标准!Q7+'SMART LEARNING HOLDING'!Q7+'SMART AI LIMITED'!Q7+'HK01'!Q7-(SUMIFS(合并抵消!$J:$J,合并抵消!$E:$E,$E7,合并抵消!$A:$A,Q$2)-SUMIFS(合并抵消!$K:$K,合并抵消!$E:$E,$E7,合并抵消!$A:$A,Q$2)) | R7: =SUM(F7:Q7)
A8: 收入 | B8: 售后收入 | D8: 供应商赔偿款 | E8: Q0202 | F8: =浙江精准学!F8+知识跳跳!F8+海南精准学!F8+实时查!F8+目标准!F8+'SMART LEARNING HOLDING'!F8+'SMART AI LIMITED'!F8+'HK01'!F8-(SUMIFS(合并抵消!$J:$J,合并抵消!$E:$E,$E8,合并抵消!$A:$A,F$2)-SUMIFS(合并抵消!$K:$K,合并抵消!$E:$E,$E8,合并抵消!$A:$A,F$2)) | G8: =浙江精准学!G8+知识跳跳!G8+海南精准学!G8+实时查!G8+目标准!G8+'SMART LEARNING HOLDING'!G8+'SMART AI LIMITED'!G8+'HK01'!G8-(SUMIFS(合并抵消!$J:$J,合并抵消!$E:$E,$E8,合并抵消!$A:$A,G$2)-SUMIFS(合并抵消!$K:$K,合并抵消!$E:$E,$E8,合并抵消!$A:$A,G$2)) | H8: =浙江精准学!H8+知识跳跳!H8+海南精准学!H8+实时查!H8+目标准!H8+'SMART LEARNING HOLDING'!H8+'SMART AI LIMITED'!H8+'HK01'!H8-(SUMIFS(合并抵消!$J:$J,合并抵消!$E:$E,$E8,合并抵消!$A:$A,H$2)-SUMIFS(合并抵消!$K:$K,合并抵消!$E:$E,$E8,合并抵消!$A:$A,H$2)) | I8: =浙江精准学!I8+知识跳跳!I8+海南精准学!I8+实时查!I8+目标准!I8+'SMART LEARNING HOLDING'!I8+'SMART AI LIMITED'!I8+'HK01'!I8-(SUMIFS(合并抵消!$J:$J,合并抵消!$E:$E,$E8,合并抵消!$A:$A,I$2)-SUMIFS(合并抵消!$K:$K,合并抵消!$E:$E,$E8,合并抵消!$A:$A,I$2)) | J8: =浙江精准学!J8+知识跳跳!J8+海南精准学!J8+实时查!J8+目标准!J8+'SMART LEARNING HOLDING'!J8+'SMART AI LIMITED'!J8+'HK01'!J8-(SUMIFS(合并抵消!$J:$J,合并抵消!$E:$E,$E8,合并抵消!$A:$A,J$2)-SUMIFS(合并抵消!$K:$K,合并抵消!$E:$E,$E8,合并抵消!$A:$A,J$2)) | K8: =浙江精准学!K8+知识跳跳!K8+海南精准学!K8+实时查!K8+目标准!K8+'SMART LEARNING HOLDING'!K8+'SMART AI LIMITED'!K8+'HK01'!K8-(SUMIFS(合并抵消!$J:$J,合并抵消!$E:$E,$E8,合并抵消!$A:$A,K$2)-SUMIFS(合并抵消!$K:$K,合并抵消!$E:$E,$E8,合并抵消!$A:$A,K$2)) | L8: =浙江精准学!L8+知识跳跳!L8+海南精准学!L8+实时查!L8+目标准!L8+'SMART LEARNING HOLDING'!L8+'SMART AI LIMITED'!L8+'HK01'!L8-(SUMIFS(合并抵消!$J:$J,合并抵消!$E:$E,$E8,合并抵消!$A:$A,L$2)-SUMIFS(合并抵消!$K:$K,合并抵消!$E:$E,$E8,合并抵消!$A:$A,L$2)) | M8: =浙江精准学!M8+知识跳跳!M8+海南精准学!M8+实时查!M8+目标准!M8+'SMART LEARNING HOLDING'!M8+'SMART AI LIMITED'!M8+'HK01'!M8-(SUMIFS(合并抵消!$J:$J,合并抵消!$E:$E,$E8,合并抵消!$A:$A,M$2)-SUMIFS(合并抵消!$K:$K,合并抵消!$E:$E,$E8,合并抵消!$A:$A,M$2)) | ... Q8: =浙江精准学!Q8+知识跳跳!Q8+海南精准学!Q8+实时查!Q8+目标准!Q8+'SMART LEARNING HOLDING'!Q8+'SMART AI LIMITED'!Q8+'HK01'!Q8-(SUMIFS(合并抵消!$J:$J,合并抵消!$E:$E,$E8,合并抵消!$A:$A,Q$2)-SUMIFS(合并抵消!$K:$K,合并抵消!$E:$E,$E8,合并抵消!$A:$A,Q$2)) | R8: =SUM(F8:Q8)
A9: 收入 | B9: 政府补贴收入 | C9: 营业外收入 | D9: 政府补贴收入 | E9: Q0301 | F9: =浙江精准学!F9+知识跳跳!F9+海南精准学!F9+实时查!F9+目标准!F9+'SMART LEARNING HOLDING'!F9+'SMART AI LIMITED'!F9+'HK01'!F9-(SUMIFS(合并抵消!$J:$J,合并抵消!$E:$E,$E9,合并抵消!$A:$A,F$2)-SUMIFS(合并抵消!$K:$K,合并抵消!$E:$E,$E9,合并抵消!$A:$A,F$2)) | G9: =浙江精准学!G9+知识跳跳!G9+海南精准学!G9+实时查!G9+目标准!G9+'SMART LEARNING HOLDING'!G9+'SMART AI LIMITED'!G9+'HK01'!G9-(SUMIFS(合并抵消!$J:$J,合并抵消!$E:$E,$E9,合并抵消!$A:$A,G$2)-SUMIFS(合并抵消!$K:$K,合并抵消!$E:$E,$E9,合并抵消!$A:$A,G$2)) | H9: =浙江精准学!H9+知识跳跳!H9+海南精准学!H9+实时查!H9+目标准!H9+'SMART LEARNING HOLDING'!H9+'SMART AI LIMITED'!H9+'HK01'!H9-(SUMIFS(合并抵消!$J:$J,合并抵消!$E:$E,$E9,合并抵消!$A:$A,H$2)-SUMIFS(合并抵消!$K:$K,合并抵消!$E:$E,$E9,合并抵消!$A:$A,H$2)) | I9: =浙江精准学!I9+知识跳跳!I9+海南精准学!I9+实时查!I9+目标准!I9+'SMART LEARNING HOLDING'!I9+'SMART AI LIMITED'!I9+'HK01'!I9-(SUMIFS(合并抵消!$J:$J,合并抵消!$E:$E,$E9,合并抵消!$A:$A,I$2)-SUMIFS(合并抵消!$K:$K,合并抵消!$E:$E,$E9,合并抵消!$A:$A,I$2)) | J9: =浙江精准学!J9+知识跳跳!J9+海南精准学!J9+实时查!J9+目标准!J9+'SMART LEARNING HOLDING'!J9+'SMART AI LIMITED'!J9+'HK01'!J9-(SUMIFS(合并抵消!$J:$J,合并抵消!$E:$E,$E9,合并抵消!$A:$A,J$2)-SUMIFS(合并抵消!$K:$K,合并抵消!$E:$E,$E9,合并抵消!$A:$A,J$2)) | K9: =浙江精准学!K9+知识跳跳!K9+海南精准学!K9+实时查!K9+目标准!K9+'SMART LEARNING HOLDING'!K9+'SMART AI LIMITED'!K9+'HK01'!K9-(SUMIFS(合并抵消!$J:$J,合并抵消!$E:$E,$E9,合并抵消!$A:$A,K$2)-SUMIFS(合并抵消!$K:$K,合并抵消!$E:$E,$E9,合并抵消!$A:$A,K$2)) | L9: =浙江精准学!L9+知识跳跳!L9+海南精准学!L9+实时查!L9+目标准!L9+'SMART LEARNING HOLDING'!L9+'SMART AI LIMITED'!L9+'HK01'!L9-(SUMIFS(合并抵消!$J:$J,合并抵消!$E:$E,$E9,合并抵消!$A:$A,L$2)-SUMIFS(合并抵消!$K:$K,合并抵消!$E:$E,$E9,合并抵消!$A:$A,L$2)) | M9: =浙江精准学!M9+知识跳跳!M9+海南精准学!M9+实时查!M9+目标准!M9+'SMART LEARNING HOLDING'!M9+'SMART AI LIMITED'!M9+'HK01'!M9-(SUMIFS(合并抵消!$J:$J,合并抵消!$E:$E,$E9,合并抵消!$A:$A,M$2)-SUMIFS(合并抵消!$K:$K,合并抵消!$E:$E,$E9,合并抵消!$A:$A,M$2)) | ... Q9: =浙江精准学!Q9+知识跳跳!Q9+海南精准学!Q9+实时查!Q9+目标准!Q9+'SMART LEARNING HOLDING'!Q9+'SMART AI LIMITED'!Q9+'HK01'!Q9-(SUMIFS(合并抵消!$J:$J,合并抵消!$E:$E,$E9,合并抵消!$A:$A,Q$2)-SUMIFS(合并抵消!$K:$K,合并抵消!$E:$E,$E9,合并抵消!$A:$A,Q$2)) | R9: =SUM(F9:Q9)
A10: 收入 | B10: 利息收入 | D10: 利息收入 | E10: Q0302 | F10: =浙江精准学!F10+知识跳跳!F10+海南精准学!F10+实时查!F10+目标准!F10+'SMART LEARNING HOLDING'!F10+'SMART AI LIMITED'!F10+'HK01'!F10-(SUMIFS(合并抵消!$J:$J,合并抵消!$E:$E,$E10,合并抵消!$A:$A,F$2)-SUMIFS(合并抵消!$K:$K,合并抵消!$E:$E,$E10,合并抵消!$A:$A,F$2)) | G10: =浙江精准学!G10+知识跳跳!G10+海南精准学!G10+实时查!G10+目标准!G10+'SMART LEARNING HOLDING'!G10+'SMART AI LIMITED'!G10+'HK01'!G10-(SUMIFS(合并抵消!$J:$J,合并抵消!$E:$E,$E10,合并抵消!$A:$A,G$2)-SUMIFS(合并抵消!$K:$K,合并抵消!$E:$E,$E10,合并抵消!$A:$A,G$2)) | H10: =浙江精准学!H10+知识跳跳!H10+海南精准学!H10+实时查!H10+目标准!H10+'SMART LEARNING HOLDING'!H10+'SMART AI LIMITED'!H10+'HK01'!H10-(SUMIFS(合并抵消!$J:$J,合并抵消!$E:$E,$E10,合并抵消!$A:$A,H$2)-SUMIFS(合并抵消!$K:$K,合并抵消!$E:$E,$E10,合并抵消!$A:$A,H$2)) | I10: =浙江精准学!I10+知识跳跳!I10+海南精准学!I10+实时查!I10+目标准!I10+'SMART LEARNING HOLDING'!I10+'SMART AI LIMITED'!I10+'HK01'!I10-(SUMIFS(合并抵消!$J:$J,合并抵消!$E:$E,$E10,合并抵消!$A:$A,I$2)-SUMIFS(合并抵消!$K:$K,合并抵消!$E:$E,$E10,合并抵消!$A:$A,I$2)) | J10: =浙江精准学!J10+知识跳跳!J10+海南精准学!J10+实时查!J10+目标准!J10+'SMART LEARNING HOLDING'!J10+'SMART AI LIMITED'!J10+'HK01'!J10-(SUMIFS(合并抵消!$J:$J,合并抵消!$E:$E,$E10,合并抵消!$A:$A,J$2)-SUMIFS(合并抵消!$K:$K,合并抵消!$E:$E,$E10,合并抵消!$A:$A,J$2)) | K10: =浙江精准学!K10+知识跳跳!K10+海南精准学!K10+实时查!K10+目标准!K10+'SMART LEARNING HOLDING'!K10+'SMART AI LIMITED'!K10+'HK01'!K10-(SUMIFS(合并抵消!$J:$J,合并抵消!$E:$E,$E10,合并抵消!$A:$A,K$2)-SUMIFS(合并抵消!$K:$K,合并抵消!$E:$E,$E10,合并抵消!$A:$A,K$2)) | L10: =浙江精准学!L10+知识跳跳!L10+海南精准学!L10+实时查!L10+目标准!L10+'SMART LEARNING HOLDING'!L10+'SMART AI LIMITED'!L10+'HK01'!L10-(SUMIFS(合并抵消!$J:$J,合并抵消!$E:$E,$E10,合并抵消!$A:$A,L$2)-SUMIFS(合并抵消!$K:$K,合并抵消!$E:$E,$E10,合并抵消!$A:$A,L$2)) | M10: =浙江精准学!M10+知识跳跳!M10+海南精准学!M10+实时查!M10+目标准!M10+'SMART LEARNING HOLDING'!M10+'SMART AI LIMITED'!M10+'HK01'!M10-(SUMIFS(合并抵消!$J:$J,合并抵消!$E:$E,$E10,合并抵消!$A:$A,M$2)-SUMIFS(合并抵消!$K:$K,合并抵消!$E:$E,$E10,合并抵消!$A:$A,M$2)) | ... Q10: =浙江精准学!Q10+知识跳跳!Q10+海南精准学!Q10+实时查!Q10+目标准!Q10+'SMART LEARNING HOLDING'!Q10+'SMART AI LIMITED'!Q10+'HK01'!Q10-(SUMIFS(合并抵消!$J:$J,合并抵消!$E:$E,$E10,合并抵消!$A:$A,Q$2)-SUMIFS(合并抵消!$K:$K,合并抵消!$E:$E,$E10,合并抵消!$A:$A,Q$2)) | R10: =SUM(F10:Q10)
A11: 收入 | B11: 营业外收入 | D11: 其他收入 | E11: Q0303 | F11: =浙江精准学!F11+知识跳跳!F11+海南精准学!F11+实时查!F11+目标准!F11+'SMART LEARNING HOLDING'!F11+'SMART AI LIMITED'!F11+'HK01'!F11-(SUMIFS(合并抵消!$J:$J,合并抵消!$E:$E,$E11,合并抵消!$A:$A,F$2)-SUMIFS(合并抵消!$K:$K,合并抵消!$E:$E,$E11,合并抵消!$A:$A,F$2)) | G11: =浙江精准学!G11+知识跳跳!G11+海南精准学!G11+实时查!G11+目标准!G11+'SMART LEARNING HOLDING'!G11+'SMART AI LIMITED'!G11+'HK01'!G11-(SUMIFS(合并抵消!$J:$J,合并抵消!$E:$E,$E11,合并抵消!$A:$A,G$2)-SUMIFS(合并抵消!$K:$K,合并抵消!$E:$E,$E11,合并抵消!$A:$A,G$2)) | H11: =浙江精准学!H11+知识跳跳!H11+海南精准学!H11+实时查!H11+目标准!H11+'SMART LEARNING HOLDING'!H11+'SMART AI LIMITED'!H11+'HK01'!H11-(SUMIFS(合并抵消!$J:$J,合并抵消!$E:$E,$E11,合并抵消!$A:$A,H$2)-SUMIFS(合并抵消!$K:$K,合并抵消!$E:$E,$E11,合并抵消!$A:$A,H$2)) | I11: =浙江精准学!I11+知识跳跳!I11+海南精准学!I11+实时查!I11+目标准!I11+'SMART LEARNING HOLDING'!I11+'SMART AI LIMITED'!I11+'HK01'!I11-(SUMIFS(合并抵消!$J:$J,合并抵消!$E:$E,$E11,合并抵消!$A:$A,I$2)-SUMIFS(合并抵消!$K:$K,合并抵消!$E:$E,$E11,合并抵消!$A:$A,I$2)) | J11: =浙江精准学!J11+知识跳跳!J11+海南精准学!J11+实时查!J11+目标准!J11+'SMART LEARNING HOLDING'!J11+'SMART AI LIMITED'!J11+'HK01'!J11-(SUMIFS(合并抵消!$J:$J,合并抵消!$E:$E,$E11,合并抵消!$A:$A,J$2)-SUMIFS(合并抵消!$K:$K,合并抵消!$E:$E,$E11,合并抵消!$A:$A,J$2)) | K11: =浙江精准学!K11+知识跳跳!K11+海南精准学!K11+实时查!K11+目标准!K11+'SMART LEARNING HOLDING'!K11+'SMART AI LIMITED'!K11+'HK01'!K11-(SUMIFS(合并抵消!$J:$J,合并抵消!$E:$E,$E11,合并抵消!$A:$A,K$2)-SUMIFS(合并抵消!$K:$K,合并抵消!$E:$E,$E11,合并抵消!$A:$A,K$2)) | L11: =浙江精准学!L11+知识跳跳!L11+海南精准学!L11+实时查!L11+目标准!L11+'SMART LEARNING HOLDING'!L11+'SMART AI LIMITED'!L11+'HK01'!L11-(SUMIFS(合并抵消!$J:$J,合并抵消!$E:$E,$E11,合并抵消!$A:$A,L$2)-SUMIFS(合并抵消!$K:$K,合并抵消!$E:$E,$E11,合并抵消!$A:$A,L$2)) | M11: =浙江精准学!M11+知识跳跳!M11+海南精准学!M11+实时查!M11+目标准!M11+'SMART LEARNING HOLDING'!M11+'SMART AI LIMITED'!M11+'HK01'!M11-(SUMIFS(合并抵消!$J:$J,合并抵消!$E:$E,$E11,合并抵消!$A:$A,M$2)-SUMIFS(合并抵消!$K:$K,合并抵消!$E:$E,$E11,合并抵消!$A:$A,M$2)) | ... Q11: =浙江精准学!Q11+知识跳跳!Q11+海南精准学!Q11+实时查!Q11+目标准!Q11+'SMART LEARNING HOLDING'!Q11+'SMART AI LIMITED'!Q11+'HK01'!Q11-(SUMIFS(合并抵消!$J:$J,合并抵消!$E:$E,$E11,合并抵消!$A:$A,Q$2)-SUMIFS(合并抵消!$K:$K,合并抵消!$E:$E,$E11,合并抵消!$A:$A,Q$2)) | R11: =SUM(F11:Q11)
A12: 收入合计 | F12: =SUM(F3:F11) | G12: =SUM(G3:G11) | H12: =SUM(H3:H11) | I12: =SUM(I3:I11) | J12: =SUM(J3:J11) | K12: =SUM(K3:K11) | L12: =SUM(L3:L11) | M12: =SUM(M3:M11) | ... Q12: =SUM(Q3:Q11) | R12: =SUM(F12:Q12)
A13: 往来款项收入 | B13: 往来款项收入 | C13: 往来款项收入 | D13: 内部往来收入 | E13: Q0401 | F13: =浙江精准学!F13+知识跳跳!F13+海南精准学!F13+实时查!F13+目标准!F13+'SMART LEARNING HOLDING'!F13+'SMART AI LIMITED'!F13+'HK01'!F13-(SUMIFS(合并抵消!$J:$J,合并抵消!$E:$E,$E13,合并抵消!$A:$A,F$2)-SUMIFS(合并抵消!$K:$K,合并抵消!$E:$E,$E13,合并抵消!$A:$A,F$2)) | G13: =浙江精准学!G13+知识跳跳!G13+海南精准学!G13+实时查!G13+目标准!G13+'SMART LEARNING HOLDING'!G13+'SMART AI LIMITED'!G13+'HK01'!G13-(SUMIFS(合并抵消!$J:$J,合并抵消!$E:$E,$E13,合并抵消!$A:$A,G$2)-SUMIFS(合并抵消!$K:$K,合并抵消!$E:$E,$E13,合并抵消!$A:$A,G$2)) | H13: =浙江精准学!H13+知识跳跳!H13+海南精准学!H13+实时查!H13+目标准!H13+'SMART LEARNING HOLDING'!H13+'SMART AI LIMITED'!H13+'HK01'!H13-(SUMIFS(合并抵消!$J:$J,合并抵消!$E:$E,$E13,合并抵消!$A:$A,H$2)-SUMIFS(合并抵消!$K:$K,合并抵消!$E:$E,$E13,合并抵消!$A:$A,H$2)) | I13: =浙江精准学!I13+知识跳跳!I13+海南精准学!I13+实时查!I13+目标准!I13+'SMART LEARNING HOLDING'!I13+'SMART AI LIMITED'!I13+'HK01'!I13-(SUMIFS(合并抵消!$J:$J,合并抵消!$E:$E,$E13,合并抵消!$A:$A,I$2)-SUMIFS(合并抵消!$K:$K,合并抵消!$E:$E,$E13,合并抵消!$A:$A,I$2)) | J13: =浙江精准学!J13+知识跳跳!J13+海南精准学!J13+实时查!J13+目标准!J13+'SMART LEARNING HOLDING'!J13+'SMART AI LIMITED'!J13+'HK01'!J13-(SUMIFS(合并抵消!$J:$J,合并抵消!$E:$E,$E13,合并抵消!$A:$A,J$2)-SUMIFS(合并抵消!$K:$K,合并抵消!$E:$E,$E13,合并抵消!$A:$A,J$2)) | K13: =浙江精准学!K13+知识跳跳!K13+海南精准学!K13+实时查!K13+目标准!K13+'SMART LEARNING HOLDING'!K13+'SMART AI LIMITED'!K13+'HK01'!K13-(SUMIFS(合并抵消!$J:$J,合并抵消!$E:$E,$E13,合并抵消!$A:$A,K$2)-SUMIFS(合并抵消!$K:$K,合并抵消!$E:$E,$E13,合并抵消!$A:$A,K$2)) | L13: =浙江精准学!L13+知识跳跳!L13+海南精准学!L13+实时查!L13+目标准!L13+'SMART LEARNING HOLDING'!L13+'SMART AI LIMITED'!L13+'HK01'!L13-(SUMIFS(合并抵消!$J:$J,合并抵消!$E:$E,$E13,合并抵消!$A:$A,L$2)-SUMIFS(合并抵消!$K:$K,合并抵消!$E:$E,$E13,合并抵消!$A:$A,L$2)) | M13: =浙江精准学!M13+知识跳跳!M13+海南精准学!M13+实时查!M13+目标准!M13+'SMART LEARNING HOLDING'!M13+'SMART AI LIMITED'!M13+'HK01'!M13-(SUMIFS(合并抵消!$J:$J,合并抵消!$E:$E,$E13,合并抵消!$A:$A,M$2)-SUMIFS(合并抵消!$K:$K,合并抵消!$E:$E,$E13,合并抵消!$A:$A,M$2)) | ... Q13: =浙江精准学!Q13+知识跳跳!Q13+海南精准学!Q13+实时查!Q13+目标准!Q13+'SMART LEARNING HOLDING'!Q13+'SMART AI LIMITED'!Q13+'HK01'!Q13-(SUMIFS(合并抵消!$J:$J,合并抵消!$E:$E,$E13,合并抵消!$A:$A,Q$2)-SUMIFS(合并抵消!$K:$K,合并抵消!$E:$E,$E13,合并抵消!$A:$A,Q$2)) | R13: =SUM(F13:Q13)
A14: 往来款项收入 | B14: 往来款项收入 | D14: 外部往来收入 | E14: Q0402 | F14: =浙江精准学!F14+知识跳跳!F14+海南精准学!F14+实时查!F14+目标准!F14+'SMART LEARNING HOLDING'!F14+'SMART AI LIMITED'!F14+'HK01'!F14-(SUMIFS(合并抵消!$J:$J,合并抵消!$E:$E,$E14,合并抵消!$A:$A,F$2)-SUMIFS(合并抵消!$K:$K,合并抵消!$E:$E,$E14,合并抵消!$A:$A,F$2)) | G14: =浙江精准学!G14+知识跳跳!G14+海南精准学!G14+实时查!G14+目标准!G14+'SMART LEARNING HOLDING'!G14+'SMART AI LIMITED'!G14+'HK01'!G14-(SUMIFS(合并抵消!$J:$J,合并抵消!$E:$E,$E14,合并抵消!$A:$A,G$2)-SUMIFS(合并抵消!$K:$K,合并抵消!$E:$E,$E14,合并抵消!$A:$A,G$2)) | H14: =浙江精准学!H14+知识跳跳!H14+海南精准学!H14+实时查!H14+目标准!H14+'SMART LEARNING HOLDING'!H14+'SMART AI LIMITED'!H14+'HK01'!H14-(SUMIFS(合并抵消!$J:$J,合并抵消!$E:$E,$E14,合并抵消!$A:$A,H$2)-SUMIFS(合并抵消!$K:$K,合并抵消!$E:$E,$E14,合并抵消!$A:$A,H$2)) | I14: =浙江精准学!I14+知识跳跳!I14+海南精准学!I14+实时查!I14+目标准!I14+'SMART LEARNING HOLDING'!I14+'SMART AI LIMITED'!I14+'HK01'!I14-(SUMIFS(合并抵消!$J:$J,合并抵消!$E:$E,$E14,合并抵消!$A:$A,I$2)-SUMIFS(合并抵消!$K:$K,合并抵消!$E:$E,$E14,合并抵消!$A:$A,I$2)) | J14: =浙江精准学!J14+知识跳跳!J14+海南精准学!J14+实时查!J14+目标准!J14+'SMART LEARNING HOLDING'!J14+'SMART AI LIMITED'!J14+'HK01'!J14-(SUMIFS(合并抵消!$J:$J,合并抵消!$E:$E,$E14,合并抵消!$A:$A,J$2)-SUMIFS(合并抵消!$K:$K,合并抵消!$E:$E,$E14,合并抵消!$A:$A,J$2)) | K14: =浙江精准学!K14+知识跳跳!K14+海南精准学!K14+实时查!K14+目标准!K14+'SMART LEARNING HOLDING'!K14+'SMART AI LIMITED'!K14+'HK01'!K14-(SUMIFS(合并抵消!$J:$J,合并抵消!$E:$E,$E14,合并抵消!$A:$A,K$2)-SUMIFS(合并抵消!$K:$K,合并抵消!$E:$E,$E14,合并抵消!$A:$A,K$2)) | L14: =浙江精准学!L14+知识跳跳!L14+海南精准学!L14+实时查!L14+目标准!L14+'SMART LEARNING HOLDING'!L14+'SMART AI LIMITED'!L14+'HK01'!L14-(SUMIFS(合并抵消!$J:$J,合并抵消!$E:$E,$E14,合并抵消!$A:$A,L$2)-SUMIFS(合并抵消!$K:$K,合并抵消!$E:$E,$E14,合并抵消!$A:$A,L$2)) | M14: =浙江精准学!M14+知识跳跳!M14+海南精准学!M14+实时查!M14+目标准!M14+'SMART LEARNING HOLDING'!M14+'SMART AI LIMITED'!M14+'HK01'!M14-(SUMIFS(合并抵消!$J:$J,合并抵消!$E:$E,$E14,合并抵消!$A:$A,M$2)-SUMIFS(合并抵消!$K:$K,合并抵消!$E:$E,$E14,合并抵消!$A:$A,M$2)) | ... Q14: =浙江精准学!Q14+知识跳跳!Q14+海南精准学!Q14+实时查!Q14+目标准!Q14+'SMART LEARNING HOLDING'!Q14+'SMART AI LIMITED'!Q14+'HK01'!Q14-(SUMIFS(合并抵消!$J:$J,合并抵消!$E:$E,$E14,合并抵消!$A:$A,Q$2)-SUMIFS(合并抵消!$K:$K,合并抵消!$E:$E,$E14,合并抵消!$A:$A,Q$2)) | R14: =SUM(F14:Q14)
A15: 往来款项收入合计 | F15: =SUM(F13:F14) | G15: =SUM(G13:G14) | H15: =SUM(H13:H14) | I15: =SUM(I13:I14) | J15: =SUM(J13:J14) | K15: =SUM(K13:K14) | L15: =SUM(L13:L14) | M15: =SUM(M13:M14) | ... Q15: =SUM(Q13:Q14) | R15: =SUM(F15:Q15)
A16: 投资款收入 | B16: 投资款收入 | C16: 投资款收入 | D16: 内部投资款收入 | E16: Q0501 | F16: =浙江精准学!F16+知识跳跳!F16+海南精准学!F16+实时查!F16+目标准!F16+'SMART LEARNING HOLDING'!F16+'SMART AI LIMITED'!F16+'HK01'!F16-(SUMIFS(合并抵消!$J:$J,合并抵消!$E:$E,$E16,合并抵消!$A:$A,F$2)-SUMIFS(合并抵消!$K:$K,合并抵消!$E:$E,$E16,合并抵消!$A:$A,F$2)) | G16: =浙江精准学!G16+知识跳跳!G16+海南精准学!G16+实时查!G16+目标准!G16+'SMART LEARNING HOLDING'!G16+'SMART AI LIMITED'!G16+'HK01'!G16-(SUMIFS(合并抵消!$J:$J,合并抵消!$E:$E,$E16,合并抵消!$A:$A,G$2)-SUMIFS(合并抵消!$K:$K,合并抵消!$E:$E,$E16,合并抵消!$A:$A,G$2)) | H16: =浙江精准学!H16+知识跳跳!H16+海南精准学!H16+实时查!H16+目标准!H16+'SMART LEARNING HOLDING'!H16+'SMART AI LIMITED'!H16+'HK01'!H16-(SUMIFS(合并抵消!$J:$J,合并抵消!$E:$E,$E16,合并抵消!$A:$A,H$2)-SUMIFS(合并抵消!$K:$K,合并抵消!$E:$E,$E16,合并抵消!$A:$A,H$2)) | I16: =浙江精准学!I16+知识跳跳!I16+海南精准学!I16+实时查!I16+目标准!I16+'SMART LEARNING HOLDING'!I16+'SMART AI LIMITED'!I16+'HK01'!I16-(SUMIFS(合并抵消!$J:$J,合并抵消!$E:$E,$E16,合并抵消!$A:$A,I$2)-SUMIFS(合并抵消!$K:$K,合并抵消!$E:$E,$E16,合并抵消!$A:$A,I$2)) | J16: =浙江精准学!J16+知识跳跳!J16+海南精准学!J16+实时查!J16+目标准!J16+'SMART LEARNING HOLDING'!J16+'SMART AI LIMITED'!J16+'HK01'!J16-(SUMIFS(合并抵消!$J:$J,合并抵消!$E:$E,$E16,合并抵消!$A:$A,J$2)-SUMIFS(合并抵消!$K:$K,合并抵消!$E:$E,$E16,合并抵消!$A:$A,J$2)) | K16: =浙江精准学!K16+知识跳跳!K16+海南精准学!K16+实时查!K16+目标准!K16+'SMART LEARNING HOLDING'!K16+'SMART AI LIMITED'!K16+'HK01'!K16-(SUMIFS(合并抵消!$J:$J,合并抵消!$E:$E,$E16,合并抵消!$A:$A,K$2)-SUMIFS(合并抵消!$K:$K,合并抵消!$E:$E,$E16,合并抵消!$A:$A,K$2)) | L16: =浙江精准学!L16+知识跳跳!L16+海南精准学!L16+实时查!L16+目标准!L16+'SMART LEARNING HOLDING'!L16+'SMART AI LIMITED'!L16+'HK01'!L16-(SUMIFS(合并抵消!$J:$J,合并抵消!$E:$E,$E16,合并抵消!$A:$A,L$2)-SUMIFS(合并抵消!$K:$K,合并抵消!$E:$E,$E16,合并抵消!$A:$A,L$2)) | M16: =浙江精准学!M16+知识跳跳!M16+海南精准学!M16+实时查!M16+目标准!M16+'SMART LEARNING HOLDING'!M16+'SMART AI LIMITED'!M16+'HK01'!M16-(SUMIFS(合并抵消!$J:$J,合并抵消!$E:$E,$E16,合并抵消!$A:$A,M$2)-SUMIFS(合并抵消!$K:$K,合并抵消!$E:$E,$E16,合并抵消!$A:$A,M$2)) | ... Q16: =浙江精准学!Q16+知识跳跳!Q16+海南精准学!Q16+实时查!Q16+目标准!Q16+'SMART LEARNING HOLDING'!Q16+'SMART AI LIMITED'!Q16+'HK01'!Q16-(SUMIFS(合并抵消!$J:$J,合并抵消!$E:$E,$E16,合并抵消!$A:$A,Q$2)-SUMIFS(合并抵消!$K:$K,合并抵消!$E:$E,$E16,合并抵消!$A:$A,Q$2)) | R16: =SUM(F16:Q16)
A17: 投资款收入 | B17: 投资款收入 | D17: 外部投资款收入 | E17: Q0502 | F17: =浙江精准学!F17+知识跳跳!F17+海南精准学!F17+实时查!F17+目标准!F17+'SMART LEARNING HOLDING'!F17+'SMART AI LIMITED'!F17+'HK01'!F17-(SUMIFS(合并抵消!$J:$J,合并抵消!$E:$E,$E17,合并抵消!$A:$A,F$2)-SUMIFS(合并抵消!$K:$K,合并抵消!$E:$E,$E17,合并抵消!$A:$A,F$2)) | G17: =浙江精准学!G17+知识跳跳!G17+海南精准学!G17+实时查!G17+目标准!G17+'SMART LEARNING HOLDING'!G17+'SMART AI LIMITED'!G17+'HK01'!G17-(SUMIFS(合并抵消!$J:$J,合并抵消!$E:$E,$E17,合并抵消!$A:$A,G$2)-SUMIFS(合并抵消!$K:$K,合并抵消!$E:$E,$E17,合并抵消!$A:$A,G$2)) | H17: =浙江精准学!H17+知识跳跳!H17+海南精准学!H17+实时查!H17+目标准!H17+'SMART LEARNING HOLDING'!H17+'SMART AI LIMITED'!H17+'HK01'!H17-(SUMIFS(合并抵消!$J:$J,合并抵消!$E:$E,$E17,合并抵消!$A:$A,H$2)-SUMIFS(合并抵消!$K:$K,合并抵消!$E:$E,$E17,合并抵消!$A:$A,H$2)) | I17: =浙江精准学!I17+知识跳跳!I17+海南精准学!I17+实时查!I17+目标准!I17+'SMART LEARNING HOLDING'!I17+'SMART AI LIMITED'!I17+'HK01'!I17-(SUMIFS(合并抵消!$J:$J,合并抵消!$E:$E,$E17,合并抵消!$A:$A,I$2)-SUMIFS(合并抵消!$K:$K,合并抵消!$E:$E,$E17,合并抵消!$A:$A,I$2)) | J17: =浙江精准学!J17+知识跳跳!J17+海南精准学!J17+实时查!J17+目标准!J17+'SMART LEARNING HOLDING'!J17+'SMART AI LIMITED'!J17+'HK01'!J17-(SUMIFS(合并抵消!$J:$J,合并抵消!$E:$E,$E17,合并抵消!$A:$A,J$2)-SUMIFS(合并抵消!$K:$K,合并抵消!$E:$E,$E17,合并抵消!$A:$A,J$2)) | K17: =浙江精准学!K17+知识跳跳!K17+海南精准学!K17+实时查!K17+目标准!K17+'SMART LEARNING HOLDING'!K17+'SMART AI LIMITED'!K17+'HK01'!K17-(SUMIFS(合并抵消!$J:$J,合并抵消!$E:$E,$E17,合并抵消!$A:$A,K$2)-SUMIFS(合并抵消!$K:$K,合并抵消!$E:$E,$E17,合并抵消!$A:$A,K$2)) | L17: =浙江精准学!L17+知识跳跳!L17+海南精准学!L17+实时查!L17+目标准!L17+'SMART LEARNING HOLDING'!L17+'SMART AI LIMITED'!L17+'HK01'!L17-(SUMIFS(合并抵消!$J:$J,合并抵消!$E:$E,$E17,合并抵消!$A:$A,L$2)-SUMIFS(合并抵消!$K:$K,合并抵消!$E:$E,$E17,合并抵消!$A:$A,L$2)) | M17: =浙江精准学!M17+知识跳跳!M17+海南精准学!M17+实时查!M17+目标准!M17+'SMART LEARNING HOLDING'!M17+'SMART AI LIMITED'!M17+'HK01'!M17-(SUMIFS(合并抵消!$J:$J,合并抵消!$E:$E,$E17,合并抵消!$A:$A,M$2)-SUMIFS(合并抵消!$K:$K,合并抵消!$E:$E,$E17,合并抵消!$A:$A,M$2)) | ... Q17: =浙江精准学!Q17+知识跳跳!Q17+海南精准学!Q17+实时查!Q17+目标准!Q17+'SMART LEARNING HOLDING'!Q17+'SMART AI LIMITED'!Q17+'HK01'!Q17-(SUMIFS(合并抵消!$J:$J,合并抵消!$E:$E,$E17,合并抵消!$A:$A,Q$2)-SUMIFS(合并抵消!$K:$K,合并抵消!$E:$E,$E17,合并抵消!$A:$A,Q$2)) | R17: =SUM(F17:Q17)
A18: 投资款收入合计 | F18: =SUM(F16:F17) | G18: =SUM(G16:G17) | H18: =SUM(H16:H17) | I18: =SUM(I16:I17) | J18: =SUM(J16:J17) | K18: =SUM(K16:K17) | L18: =SUM(L16:L17) | M18: =SUM(M16:M17) | ... Q18: =SUM(Q16:Q17) | R18: =SUM(F18:Q18)
A19: 收款合计 | F19: =ROUND(F12+F15+F18,2) | G19: =ROUND(G12+G15+G18,2) | H19: =ROUND(H12+H15+H18,2) | I19: =ROUND(I12+I15+I18,2) | J19: =ROUND(J12+J15+J18,2) | K19: =ROUND(K12+K15+K18,2) | L19: =ROUND(L12+L15+L18,2) | M19: =ROUND(M12+M15+M18,2) | ... Q19: =ROUND(Q12+Q15+Q18,2) | R19: =SUM(F19:Q19)
A20: 往来款项支出 | B20: 往来款项支出 | C20: 往来款项支出 | D20: 内部往来支出 | E20: Q0601 | F20: =浙江精准学!F20+知识跳跳!F20+海南精准学!F20+实时查!F20+目标准!F20+'SMART LEARNING HOLDING'!F20+'SMART AI LIMITED'!F20+'HK01'!F20-(-SUMIFS(合并抵消!$J:$J,合并抵消!$E:$E,$E20,合并抵消!$A:$A,F$2)+SUMIFS(合并抵消!$K:$K,合并抵消!$E:$E,$E20,合并抵消!$A:$A,F$2)) | G20: =浙江精准学!G20+知识跳跳!G20+海南精准学!G20+实时查!G20+目标准!G20+'SMART LEARNING HOLDING'!G20+'SMART AI LIMITED'!G20+'HK01'!G20-(-SUMIFS(合并抵消!$J:$J,合并抵消!$E:$E,$E20,合并抵消!$A:$A,G$2)+SUMIFS(合并抵消!$K:$K,合并抵消!$E:$E,$E20,合并抵消!$A:$A,G$2)) | H20: =浙江精准学!H20+知识跳跳!H20+海南精准学!H20+实时查!H20+目标准!H20+'SMART LEARNING HOLDING'!H20+'SMART AI LIMITED'!H20+'HK01'!H20-(-SUMIFS(合并抵消!$J:$J,合并抵消!$E:$E,$E20,合并抵消!$A:$A,H$2)+SUMIFS(合并抵消!$K:$K,合并抵消!$E:$E,$E20,合并抵消!$A:$A,H$2)) | I20: =浙江精准学!I20+知识跳跳!I20+海南精准学!I20+实时查!I20+目标准!I20+'SMART LEARNING HOLDING'!I20+'SMART AI LIMITED'!I20+'HK01'!I20-(-SUMIFS(合并抵消!$J:$J,合并抵消!$E:$E,$E20,合并抵消!$A:$A,I$2)+SUMIFS(合并抵消!$K:$K,合并抵消!$E:$E,$E20,合并抵消!$A:$A,I$2)) | J20: =浙江精准学!J20+知识跳跳!J20+海南精准学!J20+实时查!J20+目标准!J20+'SMART LEARNING HOLDING'!J20+'SMART AI LIMITED'!J20+'HK01'!J20-(-SUMIFS(合并抵消!$J:$J,合并抵消!$E:$E,$E20,合并抵消!$A:$A,J$2)+SUMIFS(合并抵消!$K:$K,合并抵消!$E:$E,$E20,合并抵消!$A:$A,J$2)) | K20: =浙江精准学!K20+知识跳跳!K20+海南精准学!K20+实时查!K20+目标准!K20+'SMART LEARNING HOLDING'!K20+'SMART AI LIMITED'!K20+'HK01'!K20-(-SUMIFS(合并抵消!$J:$J,合并抵消!$E:$E,$E20,合并抵消!$A:$A,K$2)+SUMIFS(合并抵消!$K:$K,合并抵消!$E:$E,$E20,合并抵消!$A:$A,K$2)) | L20: =浙江精准学!L20+知识跳跳!L20+海南精准学!L20+实时查!L20+目标准!L20+'SMART LEARNING HOLDING'!L20+'SMART AI LIMITED'!L20+'HK01'!L20-(-SUMIFS(合并抵消!$J:$J,合并抵消!$E:$E,$E20,合并抵消!$A:$A,L$2)+SUMIFS(合并抵消!$K:$K,合并抵消!$E:$E,$E20,合并抵消!$A:$A,L$2)) | M20: =浙江精准学!M20+知识跳跳!M20+海南精准学!M20+实时查!M20+目标准!M20+'SMART LEARNING HOLDING'!M20+'SMART AI LIMITED'!M20+'HK01'!M20-(-SUMIFS(合并抵消!$J:$J,合并抵消!$E:$E,$E20,合并抵消!$A:$A,M$2)+SUMIFS(合并抵消!$K:$K,合并抵消!$E:$E,$E20,合并抵消!$A:$A,M$2)) | ... Q20: =浙江精准学!Q20+知识跳跳!Q20+海南精准学!Q20+实时查!Q20+目标准!Q20+'SMART LEARNING HOLDING'!Q20+'SMART AI LIMITED'!Q20+'HK01'!Q20-(-SUMIFS(合并抵消!$J:$J,合并抵消!$E:$E,$E20,合并抵消!$A:$A,Q$2)+SUMIFS(合并抵消!$K:$K,合并抵消!$E:$E,$E20,合并抵消!$A:$A,Q$2)) | R20: =SUM(F20:Q20)
A21: 往来款项支出 | B21: 往来款项支出 | D21: 外部往来支出 | E21: Q0602 | F21: =浙江精准学!F21+知识跳跳!F21+海南精准学!F21+实时查!F21+目标准!F21+'SMART LEARNING HOLDING'!F21+'SMART AI LIMITED'!F21+'HK01'!F21-(-SUMIFS(合并抵消!$J:$J,合并抵消!$E:$E,$E21,合并抵消!$A:$A,F$2)+SUMIFS(合并抵消!$K:$K,合并抵消!$E:$E,$E21,合并抵消!$A:$A,F$2)) | G21: =浙江精准学!G21+知识跳跳!G21+海南精准学!G21+实时查!G21+目标准!G21+'SMART LEARNING HOLDING'!G21+'SMART AI LIMITED'!G21+'HK01'!G21-(-SUMIFS(合并抵消!$J:$J,合并抵消!$E:$E,$E21,合并抵消!$A:$A,G$2)+SUMIFS(合并抵消!$K:$K,合并抵消!$E:$E,$E21,合并抵消!$A:$A,G$2)) | H21: =浙江精准学!H21+知识跳跳!H21+海南精准学!H21+实时查!H21+目标准!H21+'SMART LEARNING HOLDING'!H21+'SMART AI LIMITED'!H21+'HK01'!H21-(-SUMIFS(合并抵消!$J:$J,合并抵消!$E:$E,$E21,合并抵消!$A:$A,H$2)+SUMIFS(合并抵消!$K:$K,合并抵消!$E:$E,$E21,合并抵消!$A:$A,H$2)) | I21: =浙江精准学!I21+知识跳跳!I21+海南精准学!I21+实时查!I21+目标准!I21+'SMART LEARNING HOLDING'!I21+'SMART AI LIMITED'!I21+'HK01'!I21-(-SUMIFS(合并抵消!$J:$J,合并抵消!$E:$E,$E21,合并抵消!$A:$A,I$2)+SUMIFS(合并抵消!$K:$K,合并抵消!$E:$E,$E21,合并抵消!$A:$A,I$2)) | J21: =浙江精准学!J21+知识跳跳!J21+海南精准学!J21+实时查!J21+目标准!J21+'SMART LEARNING HOLDING'!J21+'SMART AI LIMITED'!J21+'HK01'!J21-(-SUMIFS(合并抵消!$J:$J,合并抵消!$E:$E,$E21,合并抵消!$A:$A,J$2)+SUMIFS(合并抵消!$K:$K,合并抵消!$E:$E,$E21,合并抵消!$A:$A,J$2)) | K21: =浙江精准学!K21+知识跳跳!K21+海南精准学!K21+实时查!K21+目标准!K21+'SMART LEARNING HOLDING'!K21+'SMART AI LIMITED'!K21+'HK01'!K21-(-SUMIFS(合并抵消!$J:$J,合并抵消!$E:$E,$E21,合并抵消!$A:$A,K$2)+SUMIFS(合并抵消!$K:$K,合并抵消!$E:$E,$E21,合并抵消!$A:$A,K$2)) | L21: =浙江精准学!L21+知识跳跳!L21+海南精准学!L21+实时查!L21+目标准!L21+'SMART LEARNING HOLDING'!L21+'SMART AI LIMITED'!L21+'HK01'!L21-(-SUMIFS(合并抵消!$J:$J,合并抵消!$E:$E,$E21,合并抵消!$A:$A,L$2)+SUMIFS(合并抵消!$K:$K,合并抵消!$E:$E,$E21,合并抵消!$A:$A,L$2)) | M21: =浙江精准学!M21+知识跳跳!M21+海南精准学!M21+实时查!M21+目标准!M21+'SMART LEARNING HOLDING'!M21+'SMART AI LIMITED'!M21+'HK01'!M21-(-SUMIFS(合并抵消!$J:$J,合并抵消!$E:$E,$E21,合并抵消!$A:$A,M$2)+SUMIFS(合并抵消!$K:$K,合并抵消!$E:$E,$E21,合并抵消!$A:$A,M$2)) | ... Q21: =浙江精准学!Q21+知识跳跳!Q21+海南精准学!Q21+实时查!Q21+目标准!Q21+'SMART LEARNING HOLDING'!Q21+'SMART AI LIMITED'!Q21+'HK01'!Q21-(-SUMIFS(合并抵消!$J:$J,合并抵消!$E:$E,$E21,合并抵消!$A:$A,Q$2)+SUMIFS(合并抵消!$K:$K,合并抵消!$E:$E,$E21,合并抵消!$A:$A,Q$2)) | R21: =SUM(F21:Q21)
A22: 往来款项支出合计 | F22: =SUM(F20:F21) | G22: =SUM(G20:G21) | H22: =SUM(H20:H21) | I22: =SUM(I20:I21) | J22: =SUM(J20:J21) | K22: =SUM(K20:K21) | L22: =SUM(L20:L21) | M22: =SUM(M20:M21) | ... Q22: =SUM(Q20:Q21) | R22: =SUM(F22:Q22)
A23: 投资款支出 | B23: 投资款支出 | C23: 投资款支出 | D23: 内部投资款支出 | E23: Q0701 | F23: =浙江精准学!F23+知识跳跳!F23+海南精准学!F23+实时查!F23+目标准!F23+'SMART LEARNING HOLDING'!F23+'SMART AI LIMITED'!F23+'HK01'!F23-(-SUMIFS(合并抵消!$J:$J,合并抵消!$E:$E,$E23,合并抵消!$A:$A,F$2)+SUMIFS(合并抵消!$K:$K,合并抵消!$E:$E,$E23,合并抵消!$A:$A,F$2)) | G23: =浙江精准学!G23+知识跳跳!G23+海南精准学!G23+实时查!G23+目标准!G23+'SMART LEARNING HOLDING'!G23+'SMART AI LIMITED'!G23+'HK01'!G23-(-SUMIFS(合并抵消!$J:$J,合并抵消!$E:$E,$E23,合并抵消!$A:$A,G$2)+SUMIFS(合并抵消!$K:$K,合并抵消!$E:$E,$E23,合并抵消!$A:$A,G$2)) | H23: =浙江精准学!H23+知识跳跳!H23+海南精准学!H23+实时查!H23+目标准!H23+'SMART LEARNING HOLDING'!H23+'SMART AI LIMITED'!H23+'HK01'!H23-(-SUMIFS(合并抵消!$J:$J,合并抵消!$E:$E,$E23,合并抵消!$A:$A,H$2)+SUMIFS(合并抵消!$K:$K,合并抵消!$E:$E,$E23,合并抵消!$A:$A,H$2)) | I23: =浙江精准学!I23+知识跳跳!I23+海南精准学!I23+实时查!I23+目标准!I23+'SMART LEARNING HOLDING'!I23+'SMART AI LIMITED'!I23+'HK01'!I23-(-SUMIFS(合并抵消!$J:$J,合并抵消!$E:$E,$E23,合并抵消!$A:$A,I$2)+SUMIFS(合并抵消!$K:$K,合并抵消!$E:$E,$E23,合并抵消!$A:$A,I$2)) | J23: =浙江精准学!J23+知识跳跳!J23+海南精准学!J23+实时查!J23+目标准!J23+'SMART LEARNING HOLDING'!J23+'SMART AI LIMITED'!J23+'HK01'!J23-(-SUMIFS(合并抵消!$J:$J,合并抵消!$E:$E,$E23,合并抵消!$A:$A,J$2)+SUMIFS(合并抵消!$K:$K,合并抵消!$E:$E,$E23,合并抵消!$A:$A,J$2)) | K23: =浙江精准学!K23+知识跳跳!K23+海南精准学!K23+实时查!K23+目标准!K23+'SMART LEARNING HOLDING'!K23+'SMART AI LIMITED'!K23+'HK01'!K23-(-SUMIFS(合并抵消!$J:$J,合并抵消!$E:$E,$E23,合并抵消!$A:$A,K$2)+SUMIFS(合并抵消!$K:$K,合并抵消!$E:$E,$E23,合并抵消!$A:$A,K$2)) | L23: =浙江精准学!L23+知识跳跳!L23+海南精准学!L23+实时查!L23+目标准!L23+'SMART LEARNING HOLDING'!L23+'SMART AI LIMITED'!L23+'HK01'!L23-(-SUMIFS(合并抵消!$J:$J,合并抵消!$E:$E,$E23,合并抵消!$A:$A,L$2)+SUMIFS(合并抵消!$K:$K,合并抵消!$E:$E,$E23,合并抵消!$A:$A,L$2)) | M23: =浙江精准学!M23+知识跳跳!M23+海南精准学!M23+实时查!M23+目标准!M23+'SMART LEARNING HOLDING'!M23+'SMART AI LIMITED'!M23+'HK01'!M23-(-SUMIFS(合并抵消!$J:$J,合并抵消!$E:$E,$E23,合并抵消!$A:$A,M$2)+SUMIFS(合并抵消!$K:$K,合并抵消!$E:$E,$E23,合并抵消!$A:$A,M$2)) | ... Q23: =浙江精准学!Q23+知识跳跳!Q23+海南精准学!Q23+实时查!Q23+目标准!Q23+'SMART LEARNING HOLDING'!Q23+'SMART AI LIMITED'!Q23+'HK01'!Q23-(-SUMIFS(合并抵消!$J:$J,合并抵消!$E:$E,$E23,合并抵消!$A:$A,Q$2)+SUMIFS(合并抵消!$K:$K,合并抵消!$E:$E,$E23,合并抵消!$A:$A,Q$2)) | R23: =SUM(F23:Q23)
A24: 投资款支出合计 | F24: =SUM(F23:F23) | G24: =SUM(G23:G23) | H24: =SUM(H23:H23) | I24: =SUM(I23:I23) | J24: =SUM(J23:J23) | K24: =SUM(K23:K23) | L24: =SUM(L23:L23) | M24: =SUM(M23:M23) | ... Q24: =SUM(Q23:Q23) | R24: =SUM(F24:Q24)
A25: 人工成本 | B25: 人工成本 | C25: 人工成本 | D25: 实发工资 | E25: Q0801 | F25: =浙江精准学!F25+知识跳跳!F25+海南精准学!F25+实时查!F25+目标准!F25+'SMART LEARNING HOLDING'!F25+'SMART AI LIMITED'!F25+'HK01'!F25-(-SUMIFS(合并抵消!$J:$J,合并抵消!$E:$E,$E25,合并抵消!$A:$A,F$2)+SUMIFS(合并抵消!$K:$K,合并抵消!$E:$E,$E25,合并抵消!$A:$A,F$2)) | G25: =浙江精准学!G25+知识跳跳!G25+海南精准学!G25+实时查!G25+目标准!G25+'SMART LEARNING HOLDING'!G25+'SMART AI LIMITED'!G25+'HK01'!G25-(-SUMIFS(合并抵消!$J:$J,合并抵消!$E:$E,$E25,合并抵消!$A:$A,G$2)+SUMIFS(合并抵消!$K:$K,合并抵消!$E:$E,$E25,合并抵消!$A:$A,G$2)) | H25: =浙江精准学!H25+知识跳跳!H25+海南精准学!H25+实时查!H25+目标准!H25+'SMART LEARNING HOLDING'!H25+'SMART AI LIMITED'!H25+'HK01'!H25-(-SUMIFS(合并抵消!$J:$J,合并抵消!$E:$E,$E25,合并抵消!$A:$A,H$2)+SUMIFS(合并抵消!$K:$K,合并抵消!$E:$E,$E25,合并抵消!$A:$A,H$2)) | I25: =浙江精准学!I25+知识跳跳!I25+海南精准学!I25+实时查!I25+目标准!I25+'SMART LEARNING HOLDING'!I25+'SMART AI LIMITED'!I25+'HK01'!I25-(-SUMIFS(合并抵消!$J:$J,合并抵消!$E:$E,$E25,合并抵消!$A:$A,I$2)+SUMIFS(合并抵消!$K:$K,合并抵消!$E:$E,$E25,合并抵消!$A:$A,I$2)) | J25: =浙江精准学!J25+知识跳跳!J25+海南精准学!J25+实时查!J25+目标准!J25+'SMART LEARNING HOLDING'!J25+'SMART AI LIMITED'!J25+'HK01'!J25-(-SUMIFS(合并抵消!$J:$J,合并抵消!$E:$E,$E25,合并抵消!$A:$A,J$2)+SUMIFS(合并抵消!$K:$K,合并抵消!$E:$E,$E25,合并抵消!$A:$A,J$2)) | K25: =浙江精准学!K25+知识跳跳!K25+海南精准学!K25+实时查!K25+目标准!K25+'SMART LEARNING HOLDING'!K25+'SMART AI LIMITED'!K25+'HK01'!K25-(-SUMIFS(合并抵消!$J:$J,合并抵消!$E:$E,$E25,合并抵消!$A:$A,K$2)+SUMIFS(合并抵消!$K:$K,合并抵消!$E:$E,$E25,合并抵消!$A:$A,K$2)) | L25: =浙江精准学!L25+知识跳跳!L25+海南精准学!L25+实时查!L25+目标准!L25+'SMART LEARNING HOLDING'!L25+'SMART AI LIMITED'!L25+'HK01'!L25-(-SUMIFS(合并抵消!$J:$J,合并抵消!$E:$E,$E25,合并抵消!$A:$A,L$2)+SUMIFS(合并抵消!$K:$K,合并抵消!$E:$E,$E25,合并抵消!$A:$A,L$2)) | M25: =浙江精准学!M25+知识跳跳!M25+海南精准学!M25+实时查!M25+目标准!M25+'SMART LEARNING HOLDING'!M25+'SMART AI LIMITED'!M25+'HK01'!M25-(-SUMIFS(合并抵消!$J:$J,合并抵消!$E:$E,$E25,合并抵消!$A:$A,M$2)+SUMIFS(合并抵消!$K:$K,合并抵消!$E:$E,$E25,合并抵消!$A:$A,M$2)) | ... Q25: =浙江精准学!Q25+知识跳跳!Q25+海南精准学!Q25+实时查!Q25+目标准!Q25+'SMART LEARNING HOLDING'!Q25+'SMART AI LIMITED'!Q25+'HK01'!Q25-(-SUMIFS(合并抵消!$J:$J,合并抵消!$E:$E,$E25,合并抵消!$A:$A,Q$2)+SUMIFS(合并抵消!$K:$K,合并抵消!$E:$E,$E25,合并抵消!$A:$A,Q$2)) | R25: =SUM(F25:Q25)
A26: 人工成本 | B26: 人工成本 | D26: 奖金 | E26: Q0802 | F26: =浙江精准学!F26+知识跳跳!F26+海南精准学!F26+实时查!F26+目标准!F26+'SMART LEARNING HOLDING'!F26+'SMART AI LIMITED'!F26+'HK01'!F26-(-SUMIFS(合并抵消!$J:$J,合并抵消!$E:$E,$E26,合并抵消!$A:$A,F$2)+SUMIFS(合并抵消!$K:$K,合并抵消!$E:$E,$E26,合并抵消!$A:$A,F$2)) | G26: =浙江精准学!G26+知识跳跳!G26+海南精准学!G26+实时查!G26+目标准!G26+'SMART LEARNING HOLDING'!G26+'SMART AI LIMITED'!G26+'HK01'!G26-(-SUMIFS(合并抵消!$J:$J,合并抵消!$E:$E,$E26,合并抵消!$A:$A,G$2)+SUMIFS(合并抵消!$K:$K,合并抵消!$E:$E,$E26,合并抵消!$A:$A,G$2)) | H26: =浙江精准学!H26+知识跳跳!H26+海南精准学!H26+实时查!H26+目标准!H26+'SMART LEARNING HOLDING'!H26+'SMART AI LIMITED'!H26+'HK01'!H26-(-SUMIFS(合并抵消!$J:$J,合并抵消!$E:$E,$E26,合并抵消!$A:$A,H$2)+SUMIFS(合并抵消!$K:$K,合并抵消!$E:$E,$E26,合并抵消!$A:$A,H$2)) | I26: =浙江精准学!I26+知识跳跳!I26+海南精准学!I26+实时查!I26+目标准!I26+'SMART LEARNING HOLDING'!I26+'SMART AI LIMITED'!I26+'HK01'!I26-(-SUMIFS(合并抵消!$J:$J,合并抵消!$E:$E,$E26,合并抵消!$A:$A,I$2)+SUMIFS(合并抵消!$K:$K,合并抵消!$E:$E,$E26,合并抵消!$A:$A,I$2)) | J26: =浙江精准学!J26+知识跳跳!J26+海南精准学!J26+实时查!J26+目标准!J26+'SMART LEARNING HOLDING'!J26+'SMART AI LIMITED'!J26+'HK01'!J26-(-SUMIFS(合并抵消!$J:$J,合并抵消!$E:$E,$E26,合并抵消!$A:$A,J$2)+SUMIFS(合并抵消!$K:$K,合并抵消!$E:$E,$E26,合并抵消!$A:$A,J$2)) | K26: =浙江精准学!K26+知识跳跳!K26+海南精准学!K26+实时查!K26+目标准!K26+'SMART LEARNING HOLDING'!K26+'SMART AI LIMITED'!K26+'HK01'!K26-(-SUMIFS(合并抵消!$J:$J,合并抵消!$E:$E,$E26,合并抵消!$A:$A,K$2)+SUMIFS(合并抵消!$K:$K,合并抵消!$E:$E,$E26,合并抵消!$A:$A,K$2)) | L26: =浙江精准学!L26+知识跳跳!L26+海南精准学!L26+实时查!L26+目标准!L26+'SMART LEARNING HOLDING'!L26+'SMART AI LIMITED'!L26+'HK01'!L26-(-SUMIFS(合并抵消!$J:$J,合并抵消!$E:$E,$E26,合并抵消!$A:$A,L$2)+SUMIFS(合并抵消!$K:$K,合并抵消!$E:$E,$E26,合并抵消!$A:$A,L$2)) | M26: =浙江精准学!M26+知识跳跳!M26+海南精准学!M26+实时查!M26+目标准!M26+'SMART LEARNING HOLDING'!M26+'SMART AI LIMITED'!M26+'HK01'!M26-(-SUMIFS(合并抵消!$J:$J,合并抵消!$E:$E,$E26,合并抵消!$A:$A,M$2)+SUMIFS(合并抵消!$K:$K,合并抵消!$E:$E,$E26,合并抵消!$A:$A,M$2)) | ... Q26: =浙江精准学!Q26+知识跳跳!Q26+海南精准学!Q26+实时查!Q26+目标准!Q26+'SMART LEARNING HOLDING'!Q26+'SMART AI LIMITED'!Q26+'HK01'!Q26-(-SUMIFS(合并抵消!$J:$J,合并抵消!$E:$E,$E26,合并抵消!$A:$A,Q$2)+SUMIFS(合并抵消!$K:$K,合并抵消!$E:$E,$E26,合并抵消!$A:$A,Q$2)) | R26: =SUM(F26:Q26)
A27: 人工成本 | B27: 人工成本 | D27: 社保（单位+个人） | E27: Q0803 | F27: =浙江精准学!F27+知识跳跳!F27+海南精准学!F27+实时查!F27+目标准!F27+'SMART LEARNING HOLDING'!F27+'SMART AI LIMITED'!F27+'HK01'!F27-(-SUMIFS(合并抵消!$J:$J,合并抵消!$E:$E,$E27,合并抵消!$A:$A,F$2)+SUMIFS(合并抵消!$K:$K,合并抵消!$E:$E,$E27,合并抵消!$A:$A,F$2)) | G27: =浙江精准学!G27+知识跳跳!G27+海南精准学!G27+实时查!G27+目标准!G27+'SMART LEARNING HOLDING'!G27+'SMART AI LIMITED'!G27+'HK01'!G27-(-SUMIFS(合并抵消!$J:$J,合并抵消!$E:$E,$E27,合并抵消!$A:$A,G$2)+SUMIFS(合并抵消!$K:$K,合并抵消!$E:$E,$E27,合并抵消!$A:$A,G$2)) | H27: =浙江精准学!H27+知识跳跳!H27+海南精准学!H27+实时查!H27+目标准!H27+'SMART LEARNING HOLDING'!H27+'SMART AI LIMITED'!H27+'HK01'!H27-(-SUMIFS(合并抵消!$J:$J,合并抵消!$E:$E,$E27,合并抵消!$A:$A,H$2)+SUMIFS(合并抵消!$K:$K,合并抵消!$E:$E,$E27,合并抵消!$A:$A,H$2)) | I27: =浙江精准学!I27+知识跳跳!I27+海南精准学!I27+实时查!I27+目标准!I27+'SMART LEARNING HOLDING'!I27+'SMART AI LIMITED'!I27+'HK01'!I27-(-SUMIFS(合并抵消!$J:$J,合并抵消!$E:$E,$E27,合并抵消!$A:$A,I$2)+SUMIFS(合并抵消!$K:$K,合并抵消!$E:$E,$E27,合并抵消!$A:$A,I$2)) | J27: =浙江精准学!J27+知识跳跳!J27+海南精准学!J27+实时查!J27+目标准!J27+'SMART LEARNING HOLDING'!J27+'SMART AI LIMITED'!J27+'HK01'!J27-(-SUMIFS(合并抵消!$J:$J,合并抵消!$E:$E,$E27,合并抵消!$A:$A,J$2)+SUMIFS(合并抵消!$K:$K,合并抵消!$E:$E,$E27,合并抵消!$A:$A,J$2)) | K27: =浙江精准学!K27+知识跳跳!K27+海南精准学!K27+实时查!K27+目标准!K27+'SMART LEARNING HOLDING'!K27+'SMART AI LIMITED'!K27+'HK01'!K27-(-SUMIFS(合并抵消!$J:$J,合并抵消!$E:$E,$E27,合并抵消!$A:$A,K$2)+SUMIFS(合并抵消!$K:$K,合并抵消!$E:$E,$E27,合并抵消!$A:$A,K$2)) | L27: =浙江精准学!L27+知识跳跳!L27+海南精准学!L27+实时查!L27+目标准!L27+'SMART LEARNING HOLDING'!L27+'SMART AI LIMITED'!L27+'HK01'!L27-(-SUMIFS(合并抵消!$J:$J,合并抵消!$E:$E,$E27,合并抵消!$A:$A,L$2)+SUMIFS(合并抵消!$K:$K,合并抵消!$E:$E,$E27,合并抵消!$A:$A,L$2)) | M27: =浙江精准学!M27+知识跳跳!M27+海南精准学!M27+实时查!M27+目标准!M27+'SMART LEARNING HOLDING'!M27+'SMART AI LIMITED'!M27+'HK01'!M27-(-SUMIFS(合并抵消!$J:$J,合并抵消!$E:$E,$E27,合并抵消!$A:$A,M$2)+SUMIFS(合并抵消!$K:$K,合并抵消!$E:$E,$E27,合并抵消!$A:$A,M$2)) | ... Q27: =浙江精准学!Q27+知识跳跳!Q27+海南精准学!Q27+实时查!Q27+目标准!Q27+'SMART LEARNING HOLDING'!Q27+'SMART AI LIMITED'!Q27+'HK01'!Q27-(-SUMIFS(合并抵消!$J:$J,合并抵消!$E:$E,$E27,合并抵消!$A:$A,Q$2)+SUMIFS(合并抵消!$K:$K,合并抵消!$E:$E,$E27,合并抵消!$A:$A,Q$2)) | R27: =SUM(F27:Q27)
A28: 人工成本 | B28: 人工成本 | D28: 公积金（单位+个人） | E28: Q0804 | F28: =浙江精准学!F28+知识跳跳!F28+海南精准学!F28+实时查!F28+目标准!F28+'SMART LEARNING HOLDING'!F28+'SMART AI LIMITED'!F28+'HK01'!F28-(-SUMIFS(合并抵消!$J:$J,合并抵消!$E:$E,$E28,合并抵消!$A:$A,F$2)+SUMIFS(合并抵消!$K:$K,合并抵消!$E:$E,$E28,合并抵消!$A:$A,F$2)) | G28: =浙江精准学!G28+知识跳跳!G28+海南精准学!G28+实时查!G28+目标准!G28+'SMART LEARNING HOLDING'!G28+'SMART AI LIMITED'!G28+'HK01'!G28-(-SUMIFS(合并抵消!$J:$J,合并抵消!$E:$E,$E28,合并抵消!$A:$A,G$2)+SUMIFS(合并抵消!$K:$K,合并抵消!$E:$E,$E28,合并抵消!$A:$A,G$2)) | H28: =浙江精准学!H28+知识跳跳!H28+海南精准学!H28+实时查!H28+目标准!H28+'SMART LEARNING HOLDING'!H28+'SMART AI LIMITED'!H28+'HK01'!H28-(-SUMIFS(合并抵消!$J:$J,合并抵消!$E:$E,$E28,合并抵消!$A:$A,H$2)+SUMIFS(合并抵消!$K:$K,合并抵消!$E:$E,$E28,合并抵消!$A:$A,H$2)) | I28: =浙江精准学!I28+知识跳跳!I28+海南精准学!I28+实时查!I28+目标准!I28+'SMART LEARNING HOLDING'!I28+'SMART AI LIMITED'!I28+'HK01'!I28-(-SUMIFS(合并抵消!$J:$J,合并抵消!$E:$E,$E28,合并抵消!$A:$A,I$2)+SUMIFS(合并抵消!$K:$K,合并抵消!$E:$E,$E28,合并抵消!$A:$A,I$2)) | J28: =浙江精准学!J28+知识跳跳!J28+海南精准学!J28+实时查!J28+目标准!J28+'SMART LEARNING HOLDING'!J28+'SMART AI LIMITED'!J28+'HK01'!J28-(-SUMIFS(合并抵消!$J:$J,合并抵消!$E:$E,$E28,合并抵消!$A:$A,J$2)+SUMIFS(合并抵消!$K:$K,合并抵消!$E:$E,$E28,合并抵消!$A:$A,J$2)) | K28: =浙江精准学!K28+知识跳跳!K28+海南精准学!K28+实时查!K28+目标准!K28+'SMART LEARNING HOLDING'!K28+'SMART AI LIMITED'!K28+'HK01'!K28-(-SUMIFS(合并抵消!$J:$J,合并抵消!$E:$E,$E28,合并抵消!$A:$A,K$2)+SUMIFS(合并抵消!$K:$K,合并抵消!$E:$E,$E28,合并抵消!$A:$A,K$2)) | L28: =浙江精准学!L28+知识跳跳!L28+海南精准学!L28+实时查!L28+目标准!L28+'SMART LEARNING HOLDING'!L28+'SMART AI LIMITED'!L28+'HK01'!L28-(-SUMIFS(合并抵消!$J:$J,合并抵消!$E:$E,$E28,合并抵消!$A:$A,L$2)+SUMIFS(合并抵消!$K:$K,合并抵消!$E:$E,$E28,合并抵消!$A:$A,L$2)) | M28: =浙江精准学!M28+知识跳跳!M28+海南精准学!M28+实时查!M28+目标准!M28+'SMART LEARNING HOLDING'!M28+'SMART AI LIMITED'!M28+'HK01'!M28-(-SUMIFS(合并抵消!$J:$J,合并抵消!$E:$E,$E28,合并抵消!$A:$A,M$2)+SUMIFS(合并抵消!$K:$K,合并抵消!$E:$E,$E28,合并抵消!$A:$A,M$2)) | ... Q28: =浙江精准学!Q28+知识跳跳!Q28+海南精准学!Q28+实时查!Q28+目标准!Q28+'SMART LEARNING HOLDING'!Q28+'SMART AI LIMITED'!Q28+'HK01'!Q28-(-SUMIFS(合并抵消!$J:$J,合并抵消!$E:$E,$E28,合并抵消!$A:$A,Q$2)+SUMIFS(合并抵消!$K:$K,合并抵消!$E:$E,$E28,合并抵消!$A:$A,Q$2)) | R28: =SUM(F28:Q28)
A29: 人工成本 | B29: 人工成本 | D29: 个税 | E29: Q0805 | F29: =浙江精准学!F29+知识跳跳!F29+海南精准学!F29+实时查!F29+目标准!F29+'SMART LEARNING HOLDING'!F29+'SMART AI LIMITED'!F29+'HK01'!F29-(-SUMIFS(合并抵消!$J:$J,合并抵消!$E:$E,$E29,合并抵消!$A:$A,F$2)+SUMIFS(合并抵消!$K:$K,合并抵消!$E:$E,$E29,合并抵消!$A:$A,F$2)) | G29: =浙江精准学!G29+知识跳跳!G29+海南精准学!G29+实时查!G29+目标准!G29+'SMART LEARNING HOLDING'!G29+'SMART AI LIMITED'!G29+'HK01'!G29-(-SUMIFS(合并抵消!$J:$J,合并抵消!$E:$E,$E29,合并抵消!$A:$A,G$2)+SUMIFS(合并抵消!$K:$K,合并抵消!$E:$E,$E29,合并抵消!$A:$A,G$2)) | H29: =浙江精准学!H29+知识跳跳!H29+海南精准学!H29+实时查!H29+目标准!H29+'SMART LEARNING HOLDING'!H29+'SMART AI LIMITED'!H29+'HK01'!H29-(-SUMIFS(合并抵消!$J:$J,合并抵消!$E:$E,$E29,合并抵消!$A:$A,H$2)+SUMIFS(合并抵消!$K:$K,合并抵消!$E:$E,$E29,合并抵消!$A:$A,H$2)) | I29: =浙江精准学!I29+知识跳跳!I29+海南精准学!I29+实时查!I29+目标准!I29+'SMART LEARNING HOLDING'!I29+'SMART AI LIMITED'!I29+'HK01'!I29-(-SUMIFS(合并抵消!$J:$J,合并抵消!$E:$E,$E29,合并抵消!$A:$A,I$2)+SUMIFS(合并抵消!$K:$K,合并抵消!$E:$E,$E29,合并抵消!$A:$A,I$2)) | J29: =浙江精准学!J29+知识跳跳!J29+海南精准学!J29+实时查!J29+目标准!J29+'SMART LEARNING HOLDING'!J29+'SMART AI LIMITED'!J29+'HK01'!J29-(-SUMIFS(合并抵消!$J:$J,合并抵消!$E:$E,$E29,合并抵消!$A:$A,J$2)+SUMIFS(合并抵消!$K:$K,合并抵消!$E:$E,$E29,合并抵消!$A:$A,J$2)) | K29: =浙江精准学!K29+知识跳跳!K29+海南精准学!K29+实时查!K29+目标准!K29+'SMART LEARNING HOLDING'!K29+'SMART AI LIMITED'!K29+'HK01'!K29-(-SUMIFS(合并抵消!$J:$J,合并抵消!$E:$E,$E29,合并抵消!$A:$A,K$2)+SUMIFS(合并抵消!$K:$K,合并抵消!$E:$E,$E29,合并抵消!$A:$A,K$2)) | L29: =浙江精准学!L29+知识跳跳!L29+海南精准学!L29+实时查!L29+目标准!L29+'SMART LEARNING HOLDING'!L29+'SMART AI LIMITED'!L29+'HK01'!L29-(-SUMIFS(合并抵消!$J:$J,合并抵消!$E:$E,$E29,合并抵消!$A:$A,L$2)+SUMIFS(合并抵消!$K:$K,合并抵消!$E:$E,$E29,合并抵消!$A:$A,L$2)) | M29: =浙江精准学!M29+知识跳跳!M29+海南精准学!M29+实时查!M29+目标准!M29+'SMART LEARNING HOLDING'!M29+'SMART AI LIMITED'!M29+'HK01'!M29-(-SUMIFS(合并抵消!$J:$J,合并抵消!$E:$E,$E29,合并抵消!$A:$A,M$2)+SUMIFS(合并抵消!$K:$K,合并抵消!$E:$E,$E29,合并抵消!$A:$A,M$2)) | ... Q29: =浙江精准学!Q29+知识跳跳!Q29+海南精准学!Q29+实时查!Q29+目标准!Q29+'SMART LEARNING HOLDING'!Q29+'SMART AI LIMITED'!Q29+'HK01'!Q29-(-SUMIFS(合并抵消!$J:$J,合并抵消!$E:$E,$E29,合并抵消!$A:$A,Q$2)+SUMIFS(合并抵消!$K:$K,合并抵消!$E:$E,$E29,合并抵消!$A:$A,Q$2)) | R29: =SUM(F29:Q29)
A30: 人工成本 | B30: 人工成本 | D30: 福利费 | E30: Q0806 | F30: =浙江精准学!F30+知识跳跳!F30+海南精准学!F30+实时查!F30+目标准!F30+'SMART LEARNING HOLDING'!F30+'SMART AI LIMITED'!F30+'HK01'!F30-(-SUMIFS(合并抵消!$J:$J,合并抵消!$E:$E,$E30,合并抵消!$A:$A,F$2)+SUMIFS(合并抵消!$K:$K,合并抵消!$E:$E,$E30,合并抵消!$A:$A,F$2)) | G30: =浙江精准学!G30+知识跳跳!G30+海南精准学!G30+实时查!G30+目标准!G30+'SMART LEARNING HOLDING'!G30+'SMART AI LIMITED'!G30+'HK01'!G30-(-SUMIFS(合并抵消!$J:$J,合并抵消!$E:$E,$E30,合并抵消!$A:$A,G$2)+SUMIFS(合并抵消!$K:$K,合并抵消!$E:$E,$E30,合并抵消!$A:$A,G$2)) | H30: =浙江精准学!H30+知识跳跳!H30+海南精准学!H30+实时查!H30+目标准!H30+'SMART LEARNING HOLDING'!H30+'SMART AI LIMITED'!H30+'HK01'!H30-(-SUMIFS(合并抵消!$J:$J,合并抵消!$E:$E,$E30,合并抵消!$A:$A,H$2)+SUMIFS(合并抵消!$K:$K,合并抵消!$E:$E,$E30,合并抵消!$A:$A,H$2)) | I30: =浙江精准学!I30+知识跳跳!I30+海南精准学!I30+实时查!I30+目标准!I30+'SMART LEARNING HOLDING'!I30+'SMART AI LIMITED'!I30+'HK01'!I30-(-SUMIFS(合并抵消!$J:$J,合并抵消!$E:$E,$E30,合并抵消!$A:$A,I$2)+SUMIFS(合并抵消!$K:$K,合并抵消!$E:$E,$E30,合并抵消!$A:$A,I$2)) | J30: =浙江精准学!J30+知识跳跳!J30+海南精准学!J30+实时查!J30+目标准!J30+'SMART LEARNING HOLDING'!J30+'SMART AI LIMITED'!J30+'HK01'!J30-(-SUMIFS(合并抵消!$J:$J,合并抵消!$E:$E,$E30,合并抵消!$A:$A,J$2)+SUMIFS(合并抵消!$K:$K,合并抵消!$E:$E,$E30,合并抵消!$A:$A,J$2)) | K30: =浙江精准学!K30+知识跳跳!K30+海南精准学!K30+实时查!K30+目标准!K30+'SMART LEARNING HOLDING'!K30+'SMART AI LIMITED'!K30+'HK01'!K30-(-SUMIFS(合并抵消!$J:$J,合并抵消!$E:$E,$E30,合并抵消!$A:$A,K$2)+SUMIFS(合并抵消!$K:$K,合并抵消!$E:$E,$E30,合并抵消!$A:$A,K$2)) | L30: =浙江精准学!L30+知识跳跳!L30+海南精准学!L30+实时查!L30+目标准!L30+'SMART LEARNING HOLDING'!L30+'SMART AI LIMITED'!L30+'HK01'!L30-(-SUMIFS(合并抵消!$J:$J,合并抵消!$E:$E,$E30,合并抵消!$A:$A,L$2)+SUMIFS(合并抵消!$K:$K,合并抵消!$E:$E,$E30,合并抵消!$A:$A,L$2)) | M30: =浙江精准学!M30+知识跳跳!M30+海南精准学!M30+实时查!M30+目标准!M30+'SMART LEARNING HOLDING'!M30+'SMART AI LIMITED'!M30+'HK01'!M30-(-SUMIFS(合并抵消!$J:$J,合并抵消!$E:$E,$E30,合并抵消!$A:$A,M$2)+SUMIFS(合并抵消!$K:$K,合并抵消!$E:$E,$E30,合并抵消!$A:$A,M$2)) | ... Q30: =浙江精准学!Q30+知识跳跳!Q30+海南精准学!Q30+实时查!Q30+目标准!Q30+'SMART LEARNING HOLDING'!Q30+'SMART AI LIMITED'!Q30+'HK01'!Q30-(-SUMIFS(合并抵消!$J:$J,合并抵消!$E:$E,$E30,合并抵消!$A:$A,Q$2)+SUMIFS(合并抵消!$K:$K,合并抵消!$E:$E,$E30,合并抵消!$A:$A,Q$2)) | R30: =SUM(F30:Q30)
A31: 人工成本 | B31: 人工成本 | D31: 补偿金 | E31: Q0807 | F31: =浙江精准学!F31+知识跳跳!F31+海南精准学!F31+实时查!F31+目标准!F31+'SMART LEARNING HOLDING'!F31+'SMART AI LIMITED'!F31+'HK01'!F31-(-SUMIFS(合并抵消!$J:$J,合并抵消!$E:$E,$E31,合并抵消!$A:$A,F$2)+SUMIFS(合并抵消!$K:$K,合并抵消!$E:$E,$E31,合并抵消!$A:$A,F$2)) | G31: =浙江精准学!G31+知识跳跳!G31+海南精准学!G31+实时查!G31+目标准!G31+'SMART LEARNING HOLDING'!G31+'SMART AI LIMITED'!G31+'HK01'!G31-(-SUMIFS(合并抵消!$J:$J,合并抵消!$E:$E,$E31,合并抵消!$A:$A,G$2)+SUMIFS(合并抵消!$K:$K,合并抵消!$E:$E,$E31,合并抵消!$A:$A,G$2)) | H31: =浙江精准学!H31+知识跳跳!H31+海南精准学!H31+实时查!H31+目标准!H31+'SMART LEARNING HOLDING'!H31+'SMART AI LIMITED'!H31+'HK01'!H31-(-SUMIFS(合并抵消!$J:$J,合并抵消!$E:$E,$E31,合并抵消!$A:$A,H$2)+SUMIFS(合并抵消!$K:$K,合并抵消!$E:$E,$E31,合并抵消!$A:$A,H$2)) | I31: =浙江精准学!I31+知识跳跳!I31+海南精准学!I31+实时查!I31+目标准!I31+'SMART LEARNING HOLDING'!I31+'SMART AI LIMITED'!I31+'HK01'!I31-(-SUMIFS(合并抵消!$J:$J,合并抵消!$E:$E,$E31,合并抵消!$A:$A,I$2)+SUMIFS(合并抵消!$K:$K,合并抵消!$E:$E,$E31,合并抵消!$A:$A,I$2)) | J31: =浙江精准学!J31+知识跳跳!J31+海南精准学!J31+实时查!J31+目标准!J31+'SMART LEARNING HOLDING'!J31+'SMART AI LIMITED'!J31+'HK01'!J31-(-SUMIFS(合并抵消!$J:$J,合并抵消!$E:$E,$E31,合并抵消!$A:$A,J$2)+SUMIFS(合并抵消!$K:$K,合并抵消!$E:$E,$E31,合并抵消!$A:$A,J$2)) | K31: =浙江精准学!K31+知识跳跳!K31+海南精准学!K31+实时查!K31+目标准!K31+'SMART LEARNING HOLDING'!K31+'SMART AI LIMITED'!K31+'HK01'!K31-(-SUMIFS(合并抵消!$J:$J,合并抵消!$E:$E,$E31,合并抵消!$A:$A,K$2)+SUMIFS(合并抵消!$K:$K,合并抵消!$E:$E,$E31,合并抵消!$A:$A,K$2)) | L31: =浙江精准学!L31+知识跳跳!L31+海南精准学!L31+实时查!L31+目标准!L31+'SMART LEARNING HOLDING'!L31+'SMART AI LIMITED'!L31+'HK01'!L31-(-SUMIFS(合并抵消!$J:$J,合并抵消!$E:$E,$E31,合并抵消!$A:$A,L$2)+SUMIFS(合并抵消!$K:$K,合并抵消!$E:$E,$E31,合并抵消!$A:$A,L$2)) | M31: =浙江精准学!M31+知识跳跳!M31+海南精准学!M31+实时查!M31+目标准!M31+'SMART LEARNING HOLDING'!M31+'SMART AI LIMITED'!M31+'HK01'!M31-(-SUMIFS(合并抵消!$J:$J,合并抵消!$E:$E,$E31,合并抵消!$A:$A,M$2)+SUMIFS(合并抵消!$K:$K,合并抵消!$E:$E,$E31,合并抵消!$A:$A,M$2)) | ... Q31: =浙江精准学!Q31+知识跳跳!Q31+海南精准学!Q31+实时查!Q31+目标准!Q31+'SMART LEARNING HOLDING'!Q31+'SMART AI LIMITED'!Q31+'HK01'!Q31-(-SUMIFS(合并抵消!$J:$J,合并抵消!$E:$E,$E31,合并抵消!$A:$A,Q$2)+SUMIFS(合并抵消!$K:$K,合并抵消!$E:$E,$E31,合并抵消!$A:$A,Q$2)) | R31: =SUM(F31:Q31)
